Workbook
Name titulo: Indice!$A$1:$A$18
Name titulos: 'Mis precios'!$B$35,'Mis precios'!$B$22,'Mis precios'!$B$11,'Mis precios'!$B$42,'Mis precios'!$B$71
Name titulos: 'ListaN69 09-02-2025'!$B$33,'ListaN69 09-02-2025'!$B$20,'ListaN69 09-02-2025'!$B$9,'ListaN69 09-02-2025'!$B$40,'ListaN69 09-02-2025'!$B$69

Sheet ListaN69 09-02-2025
B1: DISTRI-SAL
A7: CODIGO | B7: DESCRIPCION | C7: Cantidad x bulto | D7: IVA | E7: PRECIO SIN IVA | F7: variacion respecto a lista anterior (aplicado en lista)
AF8: =IF(AND(ISBLANK(A8),ISBLANK(B8),ISBLANK(E8)),"Blanco",IF(AND(ISBLANK(A8),NOT(ISBLANK(B8))),"Titulo",IF(AND(NOT(ISBLANK(A8)),NOT(ISBLANK(B8)),ISBLANK(E8),IFERROR(FIND("FF--",A8)>1,FALSE)),"F.Comercializacion",IF(AND(NOT(ISBLANK(A8)),NOT(ISBLANK(B8)),NOT(ISBLANK(E8)),ISERROR(VLOOKUP(A8,'ListaN68 02-02-2025'!$A$12:$E$13375,5,0))),"Nuevo",IF(AND(NOT(ISBLANK(A8)),NOT(ISBLANK(B8)),NOT(ISBLANK(E8)),AND(E8-VLOOKUP(A8,'ListaN68 02-02-2025'!$A$12:$E$13375,5,0)>=-2,E8-VLOOKUP(A8,'ListaN68 02-02-2025'!$A$12:$E$13375,5,0)<=2)),"Igual",IF(AND(NOT(ISBLANK(A8)),NOT(ISBLANK(B8)),NOT(ISBLANK(E8)),E8-VLOOKUP(A8,'ListaN68 02-02-2025'!$A$12:$E$13375,5,0)>2),"Aumento",IF(AND(NOT(ISBLANK(A8)),NOT(ISBLANK(B8)),NOT(ISBLANK(E8)),E8-VLOOKUP(A8,'ListaN68 02-02-2025'!$A$12:$E$13375,5,0)<2),"Bajo","Error en codigo"))))))) -> Blanco
B9: ELECTRONICA | AF9: =IF(AND(ISBLANK(A9),ISBLANK(B9),ISBLANK(E9)),"Blanco",IF(AND(ISBLANK(A9),NOT(ISBLANK(B9))),"Titulo",IF(AND(NOT(ISBLANK(A9)),NOT(ISBLANK(B9)),ISBLANK(E9),IFERROR(FIND("FF--",A9)>1,FALSE)),"F.Comercializacion",IF(AND(NOT(ISBLANK(A9)),NOT(ISBLANK(B9)),NOT(ISBLANK(E9)),ISERROR(VLOOKUP(A9,'ListaN68 02-02-2025'!$A$12:$E$13375,5,0))),"Nuevo",IF(AND(NOT(ISBLANK(A9)),NOT(ISBLANK(B9)),NOT(ISBLANK(E9)),AND(E9-VLOOKUP(A9,'ListaN68 02-02-2025'!$A$12:$E$13375,5,0)>=-2,E9-VLOOKUP(A9,'ListaN68 02-02-2025'!$A$12:$E$13375,5,0)<=2)),"Igual",IF(AND(NOT(ISBLANK(A9)),NOT(ISBLANK(B9)),NOT(ISBLANK(E9)),E9-VLOOKUP(A9,'ListaN68 02-02-2025'!$A$12:$E$13375,5,0)>2),"Aumento",IF(AND(NOT(ISBLANK(A9)),NOT(ISBLANK(B9)),NOT(ISBLANK(E9)),E9-VLOOKUP(A9,'ListaN68 02-02-2025'!$A$12:$E$13375,5,0)<2),"Bajo","Error en codigo"))))))) -> Titulo
AF10: =IF(AND(ISBLANK(A10),ISBLANK(B10),ISBLANK(E10)),"Blanco",IF(AND(ISBLANK(A10),NOT(ISBLANK(B10))),"Titulo",IF(AND(NOT(ISBLANK(A10)),NOT(ISBLANK(B10)),ISBLANK(E10),IFERROR(FIND("FF--",A10)>1,FALSE)),"F.Comercializacion",IF(AND(NOT(ISBLANK(A10)),NOT(ISBLANK(B10)),NOT(ISBLANK(E10)),ISERROR(VLOOKUP(A10,'ListaN68 02-02-2025'!$A$12:$E$13375,5,0))),"Nuevo",IF(AND(NOT(ISBLANK(A10)),NOT(ISBLANK(B10)),NOT(ISBLANK(E10)),AND(E10-VLOOKUP(A10,'ListaN68 02-02-2025'!$A$12:$E$13375,5,0)>=-2,E10-VLOOKUP(A10,'ListaN68 02-02-2025'!$A$12:$E$13375,5,0)<=2)),"Igual",IF(AND(NOT(ISBLANK(A10)),NOT(ISBLANK(B10)),NOT(ISBLANK(E10)),E10-VLOOKUP(A10,'ListaN68 02-02-2025'!$A$12:$E$13375,5,0)>2),"Aumento",IF(AND(NOT(ISBLANK(A10)),NOT(ISBLANK(B10)),NOT(ISBLANK(E10)),E10-VLOOKUP(A10,'ListaN68 02-02-2025'!$A$12:$E$13375,5,0)<2),"Bajo","Error en codigo"))))))) -> Blanco
A11: CRJ-11 | B11: CONECTOR MACHO RJ-11 6 CONTACTOS | C11: UM 1u | D11: 21 | E11: 56.26 | AF11: =IF(AND(ISBLANK(A11),ISBLANK(B11),ISBLANK(E11)),"Blanco",IF(AND(ISBLANK(A11),NOT(ISBLANK(B11))),"Titulo",IF(AND(NOT(ISBLANK(A11)),NOT(ISBLANK(B11)),ISBLANK(E11),IFERROR(FIND("FF--",A11)>1,FALSE)),"F.Comercializacion",IF(AND(NOT(ISBLANK(A11)),NOT(ISBLANK(B11)),NOT(ISBLANK(E11)),ISERROR(VLOOKUP(A11,'ListaN68 02-02-2025'!$A$12:$E$13375,5,0))),"Nuevo",IF(AND(NOT(ISBLANK(A11)),NOT(ISBLANK(B11)),NOT(ISBLANK(E11)),AND(E11-VLOOKUP(A11,'ListaN68 02-02-2025'!$A$12:$E$13375,5,0)>=-2,E11-VLOOKUP(A11,'ListaN68 02-02-2025'!$A$12:$E$13375,5,0)<=2)),"Igual",IF(AND(NOT(ISBLANK(A11)),NOT(ISBLANK(B11)),NOT(ISBLANK(E11)),E11-VLOOKUP(A11,'ListaN68 02-02-2025'!$A$12:$E$13375,5,0)>2),"Aumento",IF(AND(NOT(ISBLANK(A11)),NOT(ISBLANK(B11)),NOT(ISBLANK(E11)),E11-VLOOKUP(A11,'ListaN68 02-02-2025'!$A$12:$E$13375,5,0)<2),"Bajo","Error en codigo"))))))) -> Igual
A12: CRJ-45 | B12: CONECTOR MACHO RJ-45 8 CONTACTOS | C12: UM 1u | D12: 21 | E12: 118.77 | AF12: =IF(AND(ISBLANK(A12),ISBLANK(B12),ISBLANK(E12)),"Blanco",IF(AND(ISBLANK(A12),NOT(ISBLANK(B12))),"Titulo",IF(AND(NOT(ISBLANK(A12)),NOT(ISBLANK(B12)),ISBLANK(E12),IFERROR(FIND("FF--",A12)>1,FALSE)),"F.Comercializacion",IF(AND(NOT(ISBLANK(A12)),NOT(ISBLANK(B12)),NOT(ISBLANK(E12)),ISERROR(VLOOKUP(A12,'ListaN68 02-02-2025'!$A$12:$E$13375,5,0))),"Nuevo",IF(AND(NOT(ISBLANK(A12)),NOT(ISBLANK(B12)),NOT(ISBLANK(E12)),AND(E12-VLOOKUP(A12,'ListaN68 02-02-2025'!$A$12:$E$13375,5,0)>=-2,E12-VLOOKUP(A12,'ListaN68 02-02-2025'!$A$12:$E$13375,5,0)<=2)),"Igual",IF(AND(NOT(ISBLANK(A12)),NOT(ISBLANK(B12)),NOT(ISBLANK(E12)),E12-VLOOKUP(A12,'ListaN68 02-02-2025'!$A$12:$E$13375,5,0)>2),"Aumento",IF(AND(NOT(ISBLANK(A12)),NOT(ISBLANK(B12)),NOT(ISBLANK(E12)),E12-VLOOKUP(A12,'ListaN68 02-02-2025'!$A$12:$E$13375,5,0)<2),"Bajo","Error en codigo"))))))) -> Igual
A13: CRJ-9 | B13: CONECTOR MACHO RJ-9 4 CONTACTOS | C13: UM 1u | D13: 21 | E13: 56.26 | AF13: =IF(AND(ISBLANK(A13),ISBLANK(B13),ISBLANK(E13)),"Blanco",IF(AND(ISBLANK(A13),NOT(ISBLANK(B13))),"Titulo",IF(AND(NOT(ISBLANK(A13)),NOT(ISBLANK(B13)),ISBLANK(E13),IFERROR(FIND("FF--",A13)>1,FALSE)),"F.Comercializacion",IF(AND(NOT(ISBLANK(A13)),NOT(ISBLANK(B13)),NOT(ISBLANK(E13)),ISERROR(VLOOKUP(A13,'ListaN68 02-02-2025'!$A$12:$E$13375,5,0))),"Nuevo",IF(AND(NOT(ISBLANK(A13)),NOT(ISBLANK(B13)),NOT(ISBLANK(E13)),AND(E13-VLOOKUP(A13,'ListaN68 02-02-2025'!$A$12:$E$13375,5,0)>=-2,E13-VLOOKUP(A13,'ListaN68 02-02-2025'!$A$12:$E$13375,5,0)<=2)),"Igual",IF(AND(NOT(ISBLANK(A13)),NOT(ISBLANK(B13)),NOT(ISBLANK(E13)),E13-VLOOKUP(A13,'ListaN68 02-02-2025'!$A$12:$E$13375,5,0)>2),"Aumento",IF(AND(NOT(ISBLANK(A13)),NOT(ISBLANK(B13)),NOT(ISBLANK(E13)),E13-VLOOKUP(A13,'ListaN68 02-02-2025'!$A$12:$E$13375,5,0)<2),"Bajo","Error en codigo"))))))) -> Igual
A14: HDMI | B14: CABLE HDMI A HDMI X1.5MTS | C14: UM 1u | 10u | D14: 21 | E14: 3375.54 | AF14: =IF(AND(ISBLANK(A14),ISBLANK(B14),ISBLANK(E14)),"Blanco",IF(AND(ISBLANK(A14),NOT(ISBLANK(B14))),"Titulo",IF(AND(NOT(ISBLANK(A14)),NOT(ISBLANK(B14)),ISBLANK(E14),IFERROR(FIND("FF--",A14)>1,FALSE)),"F.Comercializacion",IF(AND(NOT(ISBLANK(A14)),NOT(ISBLANK(B14)),NOT(ISBLANK(E14)),ISERROR(VLOOKUP(A14,'ListaN68 02-02-2025'!$A$12:$E$13375,5,0))),"Nuevo",IF(AND(NOT(ISBLANK(A14)),NOT(ISBLANK(B14)),NOT(ISBLANK(E14)),AND(E14-VLOOKUP(A14,'ListaN68 02-02-2025'!$A$12:$E$13375,5,0)>=-2,E14-VLOOKUP(A14,'ListaN68 02-02-2025'!$A$12:$E$13375,5,0)<=2)),"Igual",IF(AND(NOT(ISBLANK(A14)),NOT(ISBLANK(B14)),NOT(ISBLANK(E14)),E14-VLOOKUP(A14,'ListaN68 02-02-2025'!$A$12:$E$13375,5,0)>2),"Aumento",IF(AND(NOT(ISBLANK(A14)),NOT(ISBLANK(B14)),NOT(ISBLANK(E14)),E14-VLOOKUP(A14,'ListaN68 02-02-2025'!$A$12:$E$13375,5,0)<2),"Bajo","Error en codigo"))))))) -> Igual
A15: USBM | B15: CABLE USB MACHO A MICRO USB 5 PINES | C15: UM 1u | D15: 21 | E15: 1931.56 | AF15: =IF(AND(ISBLANK(A15),ISBLANK(B15),ISBLANK(E15)),"Blanco",IF(AND(ISBLANK(A15),NOT(ISBLANK(B15))),"Titulo",IF(AND(NOT(ISBLANK(A15)),NOT(ISBLANK(B15)),ISBLANK(E15),IFERROR(FIND("FF--",A15)>1,FALSE)),"F.Comercializacion",IF(AND(NOT(ISBLANK(A15)),NOT(ISBLANK(B15)),NOT(ISBLANK(E15)),ISERROR(VLOOKUP(A15,'ListaN68 02-02-2025'!$A$12:$E$13375,5,0))),"Nuevo",IF(AND(NOT(ISBLANK(A15)),NOT(ISBLANK(B15)),NOT(ISBLANK(E15)),AND(E15-VLOOKUP(A15,'ListaN68 02-02-2025'!$A$12:$E$13375,5,0)>=-2,E15-VLOOKUP(A15,'ListaN68 02-02-2025'!$A$12:$E$13375,5,0)<=2)),"Igual",IF(AND(NOT(ISBLANK(A15)),NOT(ISBLANK(B15)),NOT(ISBLANK(E15)),E15-VLOOKUP(A15,'ListaN68 02-02-2025'!$A$12:$E$13375,5,0)>2),"Aumento",IF(AND(NOT(ISBLANK(A15)),NOT(ISBLANK(B15)),NOT(ISBLANK(E15)),E15-VLOOKUP(A15,'ListaN68 02-02-2025'!$A$12:$E$13375,5,0)<2),"Bajo","Error en codigo"))))))) -> Igual
A16: USBU | B16: CABLE MACHO USB A USB C 1,5MTS | C16: UM 1u | 25u | D16: 21 | E16: 2187.85 | AF16: =IF(AND(ISBLANK(A16),ISBLANK(B16),ISBLANK(E16)),"Blanco",IF(AND(ISBLANK(A16),NOT(ISBLANK(B16))),"Titulo",IF(AND(NOT(ISBLANK(A16)),NOT(ISBLANK(B16)),ISBLANK(E16),IFERROR(FIND("FF--",A16)>1,FALSE)),"F.Comercializacion",IF(AND(NOT(ISBLANK(A16)),NOT(ISBLANK(B16)),NOT(ISBLANK(E16)),ISERROR(VLOOKUP(A16,'ListaN68 02-02-2025'!$A$12:$E$13375,5,0))),"Nuevo",IF(AND(NOT(ISBLANK(A16)),NOT(ISBLANK(B16)),NOT(ISBLANK(E16)),AND(E16-VLOOKUP(A16,'ListaN68 02-02-2025'!$A$12:$E$13375,5,0)>=-2,E16-VLOOKUP(A16,'ListaN68 02-02-2025'!$A$12:$E$13375,5,0)<=2)),"Igual",IF(AND(NOT(ISBLANK(A16)),NOT(ISBLANK(B16)),NOT(ISBLANK(E16)),E16-VLOOKUP(A16,'ListaN68 02-02-2025'!$A$12:$E$13375,5,0)>2),"Aumento",IF(AND(NOT(ISBLANK(A16)),NOT(ISBLANK(B16)),NOT(ISBLANK(E16)),E16-VLOOKUP(A16,'ListaN68 02-02-2025'!$A$12:$E$13375,5,0)<2),"Bajo","Error en codigo"))))))) -> Igual
AF17: =IF(AND(ISBLANK(A17),ISBLANK(B17),ISBLANK(E17)),"Blanco",IF(AND(ISBLANK(A17),NOT(ISBLANK(B17))),"Titulo",IF(AND(NOT(ISBLANK(A17)),NOT(ISBLANK(B17)),ISBLANK(E17),IFERROR(FIND("FF--",A17)>1,FALSE)),"F.Comercializacion",IF(AND(NOT(ISBLANK(A17)),NOT(ISBLANK(B17)),NOT(ISBLANK(E17)),ISERROR(VLOOKUP(A17,'ListaN68 02-02-2025'!$A$12:$E$13375,5,0))),"Nuevo",IF(AND(NOT(ISBLANK(A17)),NOT(ISBLANK(B17)),NOT(ISBLANK(E17)),AND(E17-VLOOKUP(A17,'ListaN68 02-02-2025'!$A$12:$E$13375,5,0)>=-2,E17-VLOOKUP(A17,'ListaN68 02-02-2025'!$A$12:$E$13375,5,0)<=2)),"Igual",IF(AND(NOT(ISBLANK(A17)),NOT(ISBLANK(B17)),NOT(ISBLANK(E17)),E17-VLOOKUP(A17,'ListaN68 02-02-2025'!$A$12:$E$13375,5,0)>2),"Aumento",IF(AND(NOT(ISBLANK(A17)),NOT(ISBLANK(B17)),NOT(ISBLANK(E17)),E17-VLOOKUP(A17,'ListaN68 02-02-2025'!$A$12:$E$13375,5,0)<2),"Bajo","Error en codigo"))))))) -> Blanco
B18: TRIPLES Y ADAPTADORES | AF18: =IF(AND(ISBLANK(A18),ISBLANK(B18),ISBLANK(E18)),"Blanco",IF(AND(ISBLANK(A18),NOT(ISBLANK(B18))),"Titulo",IF(AND(NOT(ISBLANK(A18)),NOT(ISBLANK(B18)),ISBLANK(E18),IFERROR(FIND("FF--",A18)>1,FALSE)),"F.Comercializacion",IF(AND(NOT(ISBLANK(A18)),NOT(ISBLANK(B18)),NOT(ISBLANK(E18)),ISERROR(VLOOKUP(A18,'ListaN68 02-02-2025'!$A$12:$E$13375,5,0))),"Nuevo",IF(AND(NOT(ISBLANK(A18)),NOT(ISBLANK(B18)),NOT(ISBLANK(E18)),AND(E18-VLOOKUP(A18,'ListaN68 02-02-2025'!$A$12:$E$13375,5,0)>=-2,E18-VLOOKUP(A18,'ListaN68 02-02-2025'!$A$12:$E$13375,5,0)<=2)),"Igual",IF(AND(NOT(ISBLANK(A18)),NOT(ISBLANK(B18)),NOT(ISBLANK(E18)),E18-VLOOKUP(A18,'ListaN68 02-02-2025'!$A$12:$E$13375,5,0)>2),"Aumento",IF(AND(NOT(ISBLANK(A18)),NOT(ISBLANK(B18)),NOT(ISBLANK(E18)),E18-VLOOKUP(A18,'ListaN68 02-02-2025'!$A$12:$E$13375,5,0)<2),"Bajo","Error en codigo"))))))) -> Titulo
AF19: =IF(AND(ISBLANK(A19),ISBLANK(B19),ISBLANK(E19)),"Blanco",IF(AND(ISBLANK(A19),NOT(ISBLANK(B19))),"Titulo",IF(AND(NOT(ISBLANK(A19)),NOT(ISBLANK(B19)),ISBLANK(E19),IFERROR(FIND("FF--",A19)>1,FALSE)),"F.Comercializacion",IF(AND(NOT(ISBLANK(A19)),NOT(ISBLANK(B19)),NOT(ISBLANK(E19)),ISERROR(VLOOKUP(A19,'ListaN68 02-02-2025'!$A$12:$E$13375,5,0))),"Nuevo",IF(AND(NOT(ISBLANK(A19)),NOT(ISBLANK(B19)),NOT(ISBLANK(E19)),AND(E19-VLOOKUP(A19,'ListaN68 02-02-2025'!$A$12:$E$13375,5,0)>=-2,E19-VLOOKUP(A19,'ListaN68 02-02-2025'!$A$12:$E$13375,5,0)<=2)),"Igual",IF(AND(NOT(ISBLANK(A19)),NOT(ISBLANK(B19)),NOT(ISBLANK(E19)),E19-VLOOKUP(A19,'ListaN68 02-02-2025'!$A$12:$E$13375,5,0)>2),"Aumento",IF(AND(NOT(ISBLANK(A19)),NOT(ISBLANK(B19)),NOT(ISBLANK(E19)),E19-VLOOKUP(A19,'ListaN68 02-02-2025'!$A$12:$E$13375,5,0)<2),"Bajo","Error en codigo"))))))) -> Blanco
A20: 200 | B20: ADAPTADOR 2A3 T/ KALOP (M 2P - H 3P) | C20: UM 1u | 50u | 500u | D20: 21 | E20: 534.293 | AF20: =IF(AND(ISBLANK(A20),ISBLANK(B20),ISBLANK(E20)),"Blanco",IF(AND(ISBLANK(A20),NOT(ISBLANK(B20))),"Titulo",IF(AND(NOT(ISBLANK(A20)),NOT(ISBLANK(B20)),ISBLANK(E20),IFERROR(FIND("FF--",A20)>1,FALSE)),"F.Comercializacion",IF(AND(NOT(ISBLANK(A20)),NOT(ISBLANK(B20)),NOT(ISBLANK(E20)),ISERROR(VLOOKUP(A20,'ListaN68 02-02-2025'!$A$12:$E$13375,5,0))),"Nuevo",IF(AND(NOT(ISBLANK(A20)),NOT(ISBLANK(B20)),NOT(ISBLANK(E20)),AND(E20-VLOOKUP(A20,'ListaN68 02-02-2025'!$A$12:$E$13375,5,0)>=-2,E20-VLOOKUP(A20,'ListaN68 02-02-2025'!$A$12:$E$13375,5,0)<=2)),"Igual",IF(AND(NOT(ISBLANK(A20)),NOT(ISBLANK(B20)),NOT(ISBLANK(E20)),E20-VLOOKUP(A20,'ListaN68 02-02-2025'!$A$12:$E$13375,5,0)>2),"Aumento",IF(AND(NOT(ISBLANK(A20)),NOT(ISBLANK(B20)),NOT(ISBLANK(E20)),E20-VLOOKUP(A20,'ListaN68 02-02-2025'!$A$12:$E$13375,5,0)<2),"Bajo","Error en codigo"))))))) -> Igual
A21: 201 | B21: ADAPTADOR 2A3 T/ EXULT (M 2P - H 3P) | C21: UM 1u | 100u | D21: 21 | E21: 348.874 | AF21: =IF(AND(ISBLANK(A21),ISBLANK(B21),ISBLANK(E21)),"Blanco",IF(AND(ISBLANK(A21),NOT(ISBLANK(B21))),"Titulo",IF(AND(NOT(ISBLANK(A21)),NOT(ISBLANK(B21)),ISBLANK(E21),IFERROR(FIND("FF--",A21)>1,FALSE)),"F.Comercializacion",IF(AND(NOT(ISBLANK(A21)),NOT(ISBLANK(B21)),NOT(ISBLANK(E21)),ISERROR(VLOOKUP(A21,'ListaN68 02-02-2025'!$A$12:$E$13375,5,0))),"Nuevo",IF(AND(NOT(ISBLANK(A21)),NOT(ISBLANK(B21)),NOT(ISBLANK(E21)),AND(E21-VLOOKUP(A21,'ListaN68 02-02-2025'!$A$12:$E$13375,5,0)>=-2,E21-VLOOKUP(A21,'ListaN68 02-02-2025'!$A$12:$E$13375,5,0)<=2)),"Igual",IF(AND(NOT(ISBLANK(A21)),NOT(ISBLANK(B21)),NOT(ISBLANK(E21)),E21-VLOOKUP(A21,'ListaN68 02-02-2025'!$A$12:$E$13375,5,0)>2),"Aumento",IF(AND(NOT(ISBLANK(A21)),NOT(ISBLANK(B21)),NOT(ISBLANK(E21)),E21-VLOOKUP(A21,'ListaN68 02-02-2025'!$A$12:$E$13375,5,0)<2),"Bajo","Error en codigo"))))))) -> Igual
A22: 210 | B22: ADAPTADOR FICHA TURISTA | C22: UM 1u | 100u | D22: 21 | E22: 972.822 | AF22: =IF(AND(ISBLANK(A22),ISBLANK(B22),ISBLANK(E22)),"Blanco",IF(AND(ISBLANK(A22),NOT(ISBLANK(B22))),"Titulo",IF(AND(NOT(ISBLANK(A22)),NOT(ISBLANK(B22)),ISBLANK(E22),IFERROR(FIND("FF--",A22)>1,FALSE)),"F.Comercializacion",IF(AND(NOT(ISBLANK(A22)),NOT(ISBLANK(B22)),NOT(ISBLANK(E22)),ISERROR(VLOOKUP(A22,'ListaN68 02-02-2025'!$A$12:$E$13375,5,0))),"Nuevo",IF(AND(NOT(ISBLANK(A22)),NOT(ISBLANK(B22)),NOT(ISBLANK(E22)),AND(E22-VLOOKUP(A22,'ListaN68 02-02-2025'!$A$12:$E$13375,5,0)>=-2,E22-VLOOKUP(A22,'ListaN68 02-02-2025'!$A$12:$E$13375,5,0)<=2)),"Igual",IF(AND(NOT(ISBLANK(A22)),NOT(ISBLANK(B22)),NOT(ISBLANK(E22)),E22-VLOOKUP(A22,'ListaN68 02-02-2025'!$A$12:$E$13375,5,0)>2),"Aumento",IF(AND(NOT(ISBLANK(A22)),NOT(ISBLANK(B22)),NOT(ISBLANK(E22)),E22-VLOOKUP(A22,'ListaN68 02-02-2025'!$A$12:$E$13375,5,0)<2),"Bajo","Error en codigo"))))))) -> Igual
A23: 212 | B23: ADAPTADOR 3A2 MIG (PARED A F.MACHO) | C23: UM 1u | 100u | D23: 21 | E23: 919.636 | AF23: =IF(AND(ISBLANK(A23),ISBLANK(B23),ISBLANK(E23)),"Blanco",IF(AND(ISBLANK(A23),NOT(ISBLANK(B23))),"Titulo",IF(AND(NOT(ISBLANK(A23)),NOT(ISBLANK(B23)),ISBLANK(E23),IFERROR(FIND("FF--",A23)>1,FALSE)),"F.Comercializacion",IF(AND(NOT(ISBLANK(A23)),NOT(ISBLANK(B23)),NOT(ISBLANK(E23)),ISERROR(VLOOKUP(A23,'ListaN68 02-02-2025'!$A$12:$E$13375,5,0))),"Nuevo",IF(AND(NOT(ISBLANK(A23)),NOT(ISBLANK(B23)),NOT(ISBLANK(E23)),AND(E23-VLOOKUP(A23,'ListaN68 02-02-2025'!$A$12:$E$13375,5,0)>=-2,E23-VLOOKUP(A23,'ListaN68 02-02-2025'!$A$12:$E$13375,5,0)<=2)),"Igual",IF(AND(NOT(ISBLANK(A23)),NOT(ISBLANK(B23)),NOT(ISBLANK(E23)),E23-VLOOKUP(A23,'ListaN68 02-02-2025'!$A$12:$E$13375,5,0)>2),"Aumento",IF(AND(NOT(ISBLANK(A23)),NOT(ISBLANK(B23)),NOT(ISBLANK(E23)),E23-VLOOKUP(A23,'ListaN68 02-02-2025'!$A$12:$E$13375,5,0)<2),"Bajo","Error en codigo"))))))) -> Igual
A24: 215 | B24: TRIPLE IRROMPIBLE MIG | C24: UM 1u | 50u | D24: 21 | E24: 1249.887 | AF24: =IF(AND(ISBLANK(A24),ISBLANK(B24),ISBLANK(E24)),"Blanco",IF(AND(ISBLANK(A24),NOT(ISBLANK(B24))),"Titulo",IF(AND(NOT(ISBLANK(A24)),NOT(ISBLANK(B24)),ISBLANK(E24),IFERROR(FIND("FF--",A24)>1,FALSE)),"F.Comercializacion",IF(AND(NOT(ISBLANK(A24)),NOT(ISBLANK(B24)),NOT(ISBLANK(E24)),ISERROR(VLOOKUP(A24,'ListaN68 02-02-2025'!$A$12:$E$13375,5,0))),"Nuevo",IF(AND(NOT(ISBLANK(A24)),NOT(ISBLANK(B24)),NOT(ISBLANK(E24)),AND(E24-VLOOKUP(A24,'ListaN68 02-02-2025'!$A$12:$E$13375,5,0)>=-2,E24-VLOOKUP(A24,'ListaN68 02-02-2025'!$A$12:$E$13375,5,0)<=2)),"Igual",IF(AND(NOT(ISBLANK(A24)),NOT(ISBLANK(B24)),NOT(ISBLANK(E24)),E24-VLOOKUP(A24,'ListaN68 02-02-2025'!$A$12:$E$13375,5,0)>2),"Aumento",IF(AND(NOT(ISBLANK(A24)),NOT(ISBLANK(B24)),NOT(ISBLANK(E24)),E24-VLOOKUP(A24,'ListaN68 02-02-2025'!$A$12:$E$13375,5,0)<2),"Bajo","Error en codigo"))))))) -> Igual
A25: 216 | B25: TRIPLE IRROMPIBLE MIG ***CON NEUTRO**** 216 | C25: UM 1u | 50u | D25: 21 | E25: 1249.887 | AF25: =IF(AND(ISBLANK(A25),ISBLANK(B25),ISBLANK(E25)),"Blanco",IF(AND(ISBLANK(A25),NOT(ISBLANK(B25))),"Titulo",IF(AND(NOT(ISBLANK(A25)),NOT(ISBLANK(B25)),ISBLANK(E25),IFERROR(FIND("FF--",A25)>1,FALSE)),"F.Comercializacion",IF(AND(NOT(ISBLANK(A25)),NOT(ISBLANK(B25)),NOT(ISBLANK(E25)),ISERROR(VLOOKUP(A25,'ListaN68 02-02-2025'!$A$12:$E$13375,5,0))),"Nuevo",IF(AND(NOT(ISBLANK(A25)),NOT(ISBLANK(B25)),NOT(ISBLANK(E25)),AND(E25-VLOOKUP(A25,'ListaN68 02-02-2025'!$A$12:$E$13375,5,0)>=-2,E25-VLOOKUP(A25,'ListaN68 02-02-2025'!$A$12:$E$13375,5,0)<=2)),"Igual",IF(AND(NOT(ISBLANK(A25)),NOT(ISBLANK(B25)),NOT(ISBLANK(E25)),E25-VLOOKUP(A25,'ListaN68 02-02-2025'!$A$12:$E$13375,5,0)>2),"Aumento",IF(AND(NOT(ISBLANK(A25)),NOT(ISBLANK(B25)),NOT(ISBLANK(E25)),E25-VLOOKUP(A25,'ListaN68 02-02-2025'!$A$12:$E$13375,5,0)<2),"Bajo","Error en codigo"))))))) -> Igual
A26: 223 | B26: ADAPTADOR AMERICANO/ALEMAN BCO | C26: UM 1u | 100u | D26: 21 | E26: 892.423 | AF26: =IF(AND(ISBLANK(A26),ISBLANK(B26),ISBLANK(E26)),"Blanco",IF(AND(ISBLANK(A26),NOT(ISBLANK(B26))),"Titulo",IF(AND(NOT(ISBLANK(A26)),NOT(ISBLANK(B26)),ISBLANK(E26),IFERROR(FIND("FF--",A26)>1,FALSE)),"F.Comercializacion",IF(AND(NOT(ISBLANK(A26)),NOT(ISBLANK(B26)),NOT(ISBLANK(E26)),ISERROR(VLOOKUP(A26,'ListaN68 02-02-2025'!$A$12:$E$13375,5,0))),"Nuevo",IF(AND(NOT(ISBLANK(A26)),NOT(ISBLANK(B26)),NOT(ISBLANK(E26)),AND(E26-VLOOKUP(A26,'ListaN68 02-02-2025'!$A$12:$E$13375,5,0)>=-2,E26-VLOOKUP(A26,'ListaN68 02-02-2025'!$A$12:$E$13375,5,0)<=2)),"Igual",IF(AND(NOT(ISBLANK(A26)),NOT(ISBLANK(B26)),NOT(ISBLANK(E26)),E26-VLOOKUP(A26,'ListaN68 02-02-2025'!$A$12:$E$13375,5,0)>2),"Aumento",IF(AND(NOT(ISBLANK(A26)),NOT(ISBLANK(B26)),NOT(ISBLANK(E26)),E26-VLOOKUP(A26,'ListaN68 02-02-2025'!$A$12:$E$13375,5,0)<2),"Bajo","Error en codigo"))))))) -> Igual
A27: 223-N | B27: ADAPTADOR AMERICANO/ALEMAN NEGRO | C27: UM 1u | 100u | D27: 21 | E27: 892.423 | AF27: =IF(AND(ISBLANK(A27),ISBLANK(B27),ISBLANK(E27)),"Blanco",IF(AND(ISBLANK(A27),NOT(ISBLANK(B27))),"Titulo",IF(AND(NOT(ISBLANK(A27)),NOT(ISBLANK(B27)),ISBLANK(E27),IFERROR(FIND("FF--",A27)>1,FALSE)),"F.Comercializacion",IF(AND(NOT(ISBLANK(A27)),NOT(ISBLANK(B27)),NOT(ISBLANK(E27)),ISERROR(VLOOKUP(A27,'ListaN68 02-02-2025'!$A$12:$E$13375,5,0))),"Nuevo",IF(AND(NOT(ISBLANK(A27)),NOT(ISBLANK(B27)),NOT(ISBLANK(E27)),AND(E27-VLOOKUP(A27,'ListaN68 02-02-2025'!$A$12:$E$13375,5,0)>=-2,E27-VLOOKUP(A27,'ListaN68 02-02-2025'!$A$12:$E$13375,5,0)<=2)),"Igual",IF(AND(NOT(ISBLANK(A27)),NOT(ISBLANK(B27)),NOT(ISBLANK(E27)),E27-VLOOKUP(A27,'ListaN68 02-02-2025'!$A$12:$E$13375,5,0)>2),"Aumento",IF(AND(NOT(ISBLANK(A27)),NOT(ISBLANK(B27)),NOT(ISBLANK(E27)),E27-VLOOKUP(A27,'ListaN68 02-02-2025'!$A$12:$E$13375,5,0)<2),"Bajo","Error en codigo"))))))) -> Igual
A28: 224 | B28: ADAPTADOR AMERICANO/ALEMAN P/PLANA BCO | C28: UM 1u | 100u | D28: 21 | E28: 919.636 | AF28: =IF(AND(ISBLANK(A28),ISBLANK(B28),ISBLANK(E28)),"Blanco",IF(AND(ISBLANK(A28),NOT(ISBLANK(B28))),"Titulo",IF(AND(NOT(ISBLANK(A28)),NOT(ISBLANK(B28)),ISBLANK(E28),IFERROR(FIND("FF--",A28)>1,FALSE)),"F.Comercializacion",IF(AND(NOT(ISBLANK(A28)),NOT(ISBLANK(B28)),NOT(ISBLANK(E28)),ISERROR(VLOOKUP(A28,'ListaN68 02-02-2025'!$A$12:$E$13375,5,0))),"Nuevo",IF(AND(NOT(ISBLANK(A28)),NOT(ISBLANK(B28)),NOT(ISBLANK(E28)),AND(E28-VLOOKUP(A28,'ListaN68 02-02-2025'!$A$12:$E$13375,5,0)>=-2,E28-VLOOKUP(A28,'ListaN68 02-02-2025'!$A$12:$E$13375,5,0)<=2)),"Igual",IF(AND(NOT(ISBLANK(A28)),NOT(ISBLANK(B28)),NOT(ISBLANK(E28)),E28-VLOOKUP(A28,'ListaN68 02-02-2025'!$A$12:$E$13375,5,0)>2),"Aumento",IF(AND(NOT(ISBLANK(A28)),NOT(ISBLANK(B28)),NOT(ISBLANK(E28)),E28-VLOOKUP(A28,'ListaN68 02-02-2025'!$A$12:$E$13375,5,0)<2),"Bajo","Error en codigo"))))))) -> Igual
A29: 224-N | B29: ADAPTADOR AMERICANO/ALEMAN P/PLANA NEGRO | C29: UM 1u | 100u | D29: 21 | E29: 919.636 | AF29: =IF(AND(ISBLANK(A29),ISBLANK(B29),ISBLANK(E29)),"Blanco",IF(AND(ISBLANK(A29),NOT(ISBLANK(B29))),"Titulo",IF(AND(NOT(ISBLANK(A29)),NOT(ISBLANK(B29)),ISBLANK(E29),IFERROR(FIND("FF--",A29)>1,FALSE)),"F.Comercializacion",IF(AND(NOT(ISBLANK(A29)),NOT(ISBLANK(B29)),NOT(ISBLANK(E29)),ISERROR(VLOOKUP(A29,'ListaN68 02-02-2025'!$A$12:$E$13375,5,0))),"Nuevo",IF(AND(NOT(ISBLANK(A29)),NOT(ISBLANK(B29)),NOT(ISBLANK(E29)),AND(E29-VLOOKUP(A29,'ListaN68 02-02-2025'!$A$12:$E$13375,5,0)>=-2,E29-VLOOKUP(A29,'ListaN68 02-02-2025'!$A$12:$E$13375,5,0)<=2)),"Igual",IF(AND(NOT(ISBLANK(A29)),NOT(ISBLANK(B29)),NOT(ISBLANK(E29)),E29-VLOOKUP(A29,'ListaN68 02-02-2025'!$A$12:$E$13375,5,0)>2),"Aumento",IF(AND(NOT(ISBLANK(A29)),NOT(ISBLANK(B29)),NOT(ISBLANK(E29)),E29-VLOOKUP(A29,'ListaN68 02-02-2025'!$A$12:$E$13375,5,0)<2),"Bajo","Error en codigo"))))))) -> Igual
A30: 230 | B30: ADAPTADOR MULTIFUNCION | C30: UM 1u | 100u | D30: 21 | E30: 941.899 | AF30: =IF(AND(ISBLANK(A30),ISBLANK(B30),ISBLANK(E30)),"Blanco",IF(AND(ISBLANK(A30),NOT(ISBLANK(B30))),"Titulo",IF(AND(NOT(ISBLANK(A30)),NOT(ISBLANK(B30)),ISBLANK(E30),IFERROR(FIND("FF--",A30)>1,FALSE)),"F.Comercializacion",IF(AND(NOT(ISBLANK(A30)),NOT(ISBLANK(B30)),NOT(ISBLANK(E30)),ISERROR(VLOOKUP(A30,'ListaN68 02-02-2025'!$A$12:$E$13375,5,0))),"Nuevo",IF(AND(NOT(ISBLANK(A30)),NOT(ISBLANK(B30)),NOT(ISBLANK(E30)),AND(E30-VLOOKUP(A30,'ListaN68 02-02-2025'!$A$12:$E$13375,5,0)>=-2,E30-VLOOKUP(A30,'ListaN68 02-02-2025'!$A$12:$E$13375,5,0)<=2)),"Igual",IF(AND(NOT(ISBLANK(A30)),NOT(ISBLANK(B30)),NOT(ISBLANK(E30)),E30-VLOOKUP(A30,'ListaN68 02-02-2025'!$A$12:$E$13375,5,0)>2),"Aumento",IF(AND(NOT(ISBLANK(A30)),NOT(ISBLANK(B30)),NOT(ISBLANK(E30)),E30-VLOOKUP(A30,'ListaN68 02-02-2025'!$A$12:$E$13375,5,0)<2),"Bajo","Error en codigo"))))))) -> Igual
A31: LWW-K3 | B31: ADAPTADOR VIAJERO UNIVERSAL C/ FICHA | C31: UM 1u | 20u | 600u | D31: 21 | E31: 1561.215 | F31: -0.0068259386 | AF31: =IF(AND(ISBLANK(A31),ISBLANK(B31),ISBLANK(E31)),"Blanco",IF(AND(ISBLANK(A31),NOT(ISBLANK(B31))),"Titulo",IF(AND(NOT(ISBLANK(A31)),NOT(ISBLANK(B31)),ISBLANK(E31),IFERROR(FIND("FF--",A31)>1,FALSE)),"F.Comercializacion",IF(AND(NOT(ISBLANK(A31)),NOT(ISBLANK(B31)),NOT(ISBLANK(E31)),ISERROR(VLOOKUP(A31,'ListaN68 02-02-2025'!$A$12:$E$13375,5,0))),"Nuevo",IF(AND(NOT(ISBLANK(A31)),NOT(ISBLANK(B31)),NOT(ISBLANK(E31)),AND(E31-VLOOKUP(A31,'ListaN68 02-02-2025'!$A$12:$E$13375,5,0)>=-2,E31-VLOOKUP(A31,'ListaN68 02-02-2025'!$A$12:$E$13375,5,0)<=2)),"Igual",IF(AND(NOT(ISBLANK(A31)),NOT(ISBLANK(B31)),NOT(ISBLANK(E31)),E31-VLOOKUP(A31,'ListaN68 02-02-2025'!$A$12:$E$13375,5,0)>2),"Aumento",IF(AND(NOT(ISBLANK(A31)),NOT(ISBLANK(B31)),NOT(ISBLANK(E31)),E31-VLOOKUP(A31,'ListaN68 02-02-2025'!$A$12:$E$13375,5,0)<2),"Bajo","Error en codigo"))))))) -> Bajo
A32: MU-A3 | B32: ADAPTADOR VIAJERO S/USB | C32: UM 1u | 20u | 200u | D32: 21 | E32: 3417.795 | F32: -0.0068259386 | AF32: =IF(AND(ISBLANK(A32),ISBLANK(B32),ISBLANK(E32)),"Blanco",IF(AND(ISBLANK(A32),NOT(ISBLANK(B32))),"Titulo",IF(AND(NOT(ISBLANK(A32)),NOT(ISBLANK(B32)),ISBLANK(E32),IFERROR(FIND("FF--",A32)>1,FALSE)),"F.Comercializacion",IF(AND(NOT(ISBLANK(A32)),NOT(ISBLANK(B32)),NOT(ISBLANK(E32)),ISERROR(VLOOKUP(A32,'ListaN68 02-02-2025'!$A$12:$E$13375,5,0))),"Nuevo",IF(AND(NOT(ISBLANK(A32)),NOT(ISBLANK(B32)),NOT(ISBLANK(E32)),AND(E32-VLOOKUP(A32,'ListaN68 02-02-2025'!$A$12:$E$13375,5,0)>=-2,E32-VLOOKUP(A32,'ListaN68 02-02-2025'!$A$12:$E$13375,5,0)<=2)),"Igual",IF(AND(NOT(ISBLANK(A32)),NOT(ISBLANK(B32)),NOT(ISBLANK(E32)),E32-VLOOKUP(A32,'ListaN68 02-02-2025'!$A$12:$E$13375,5,0)>2),"Aumento",IF(AND(NOT(ISBLANK(A32)),NOT(ISBLANK(B32)),NOT(ISBLANK(E32)),E32-VLOOKUP(A32,'ListaN68 02-02-2025'!$A$12:$E$13375,5,0)<2),"Bajo","Error en codigo"))))))) -> Bajo
A33: MU-A4 | B33: ADAPTADOR VIAJERO C/USB | C33: UM 1u | 20u | 200u | D33: 21 | E33: 8523.39 | F33: -0.0068259386 | AF33: =IF(AND(ISBLANK(A33),ISBLANK(B33),ISBLANK(E33)),"Blanco",IF(AND(ISBLANK(A33),NOT(ISBLANK(B33))),"Titulo",IF(AND(NOT(ISBLANK(A33)),NOT(ISBLANK(B33)),ISBLANK(E33),IFERROR(FIND("FF--",A33)>1,FALSE)),"F.Comercializacion",IF(AND(NOT(ISBLANK(A33)),NOT(ISBLANK(B33)),NOT(ISBLANK(E33)),ISERROR(VLOOKUP(A33,'ListaN68 02-02-2025'!$A$12:$E$13375,5,0))),"Nuevo",IF(AND(NOT(ISBLANK(A33)),NOT(ISBLANK(B33)),NOT(ISBLANK(E33)),AND(E33-VLOOKUP(A33,'ListaN68 02-02-2025'!$A$12:$E$13375,5,0)>=-2,E33-VLOOKUP(A33,'ListaN68 02-02-2025'!$A$12:$E$13375,5,0)<=2)),"Igual",IF(AND(NOT(ISBLANK(A33)),NOT(ISBLANK(B33)),NOT(ISBLANK(E33)),E33-VLOOKUP(A33,'ListaN68 02-02-2025'!$A$12:$E$13375,5,0)>2),"Aumento",IF(AND(NOT(ISBLANK(A33)),NOT(ISBLANK(B33)),NOT(ISBLANK(E33)),E33-VLOOKUP(A33,'ListaN68 02-02-2025'!$A$12:$E$13375,5,0)<2),"Bajo","Error en codigo"))))))) -> Bajo
A34: PE-727 | B34: ADAPTADOR VIAJERO UNIVERSAL | C34: UM 1u | 20u | 1000u | D34: 21 | E34: 593.64 | F34: -0.0068259386 | AF34: =IF(AND(ISBLANK(A34),ISBLANK(B34),ISBLANK(E34)),"Blanco",IF(AND(ISBLANK(A34),NOT(ISBLANK(B34))),"Titulo",IF(AND(NOT(ISBLANK(A34)),NOT(ISBLANK(B34)),ISBLANK(E34),IFERROR(FIND("FF--",A34)>1,FALSE)),"F.Comercializacion",IF(AND(NOT(ISBLANK(A34)),NOT(ISBLANK(B34)),NOT(ISBLANK(E34)),ISERROR(VLOOKUP(A34,'ListaN68 02-02-2025'!$A$12:$E$13375,5,0))),"Nuevo",IF(AND(NOT(ISBLANK(A34)),NOT(ISBLANK(B34)),NOT(ISBLANK(E34)),AND(E34-VLOOKUP(A34,'ListaN68 02-02-2025'!$A$12:$E$13375,5,0)>=-2,E34-VLOOKUP(A34,'ListaN68 02-02-2025'!$A$12:$E$13375,5,0)<=2)),"Igual",IF(AND(NOT(ISBLANK(A34)),NOT(ISBLANK(B34)),NOT(ISBLANK(E34)),E34-VLOOKUP(A34,'ListaN68 02-02-2025'!$A$12:$E$13375,5,0)>2),"Aumento",IF(AND(NOT(ISBLANK(A34)),NOT(ISBLANK(B34)),NOT(ISBLANK(E34)),E34-VLOOKUP(A34,'ListaN68 02-02-2025'!$A$12:$E$13375,5,0)<2),"Bajo","Error en codigo"))))))) -> Bajo
AF35: =IF(AND(ISBLANK(A35),ISBLANK(B35),ISBLANK(E35)),"Blanco",IF(AND(ISBLANK(A35),NOT(ISBLANK(B35))),"Titulo",IF(AND(NOT(ISBLANK(A35)),NOT(ISBLANK(B35)),ISBLANK(E35),IFERROR(FIND("FF--",A35)>1,FALSE)),"F.Comercializacion",IF(AND(NOT(ISBLANK(A35)),NOT(ISBLANK(B35)),NOT(ISBLANK(E35)),ISERROR(VLOOKUP(A35,'ListaN68 02-02-2025'!$A$12:$E$13375,5,0))),"Nuevo",IF(AND(NOT(ISBLANK(A35)),NOT(ISBLANK(B35)),NOT(ISBLANK(E35)),AND(E35-VLOOKUP(A35,'ListaN68 02-02-2025'!$A$12:$E$13375,5,0)>=-2,E35-VLOOKUP(A35,'ListaN68 02-02-2025'!$A$12:$E$13375,5,0)<=2)),"Igual",IF(AND(NOT(ISBLANK(A35)),NOT(ISBLANK(B35)),NOT(ISBLANK(E35)),E35-VLOOKUP(A35,'ListaN68 02-02-2025'!$A$12:$E$13375,5,0)>2),"Aumento",IF(AND(NOT(ISBLANK(A35)),NOT(ISBLANK(B35)),NOT(ISBLANK(E35)),E35-VLOOKUP(A35,'ListaN68 02-02-2025'!$A$12:$E$13375,5,0)<2),"Bajo","Error en codigo"))))))) -> Blanco
B36: MULTI-FICHAS | AF36: =IF(AND(ISBLANK(A36),ISBLANK(B36),ISBLANK(E36)),"Blanco",IF(AND(ISBLANK(A36),NOT(ISBLANK(B36))),"Titulo",IF(AND(NOT(ISBLANK(A36)),NOT(ISBLANK(B36)),ISBLANK(E36),IFERROR(FIND("FF--",A36)>1,FALSE)),"F.Comercializacion",IF(AND(NOT(ISBLANK(A36)),NOT(ISBLANK(B36)),NOT(ISBLANK(E36)),ISERROR(VLOOKUP(A36,'ListaN68 02-02-2025'!$A$12:$E$13375,5,0))),"Nuevo",IF(AND(NOT(ISBLANK(A36)),NOT(ISBLANK(B36)),NOT(ISBLANK(E36)),AND(E36-VLOOKUP(A36,'ListaN68 02-02-2025'!$A$12:$E$13375,5,0)>=-2,E36-VLOOKUP(A36,'ListaN68 02-02-2025'!$A$12:$E$13375,5,0)<=2)),"Igual",IF(AND(NOT(ISBLANK(A36)),NOT(ISBLANK(B36)),NOT(ISBLANK(E36)),E36-VLOOKUP(A36,'ListaN68 02-02-2025'!$A$12:$E$13375,5,0)>2),"Aumento",IF(AND(NOT(ISBLANK(A36)),NOT(ISBLANK(B36)),NOT(ISBLANK(E36)),E36-VLOOKUP(A36,'ListaN68 02-02-2025'!$A$12:$E$13375,5,0)<2),"Bajo","Error en codigo"))))))) -> Titulo
AF37: =IF(AND(ISBLANK(A37),ISBLANK(B37),ISBLANK(E37)),"Blanco",IF(AND(ISBLANK(A37),NOT(ISBLANK(B37))),"Titulo",IF(AND(NOT(ISBLANK(A37)),NOT(ISBLANK(B37)),ISBLANK(E37),IFERROR(FIND("FF--",A37)>1,FALSE)),"F.Comercializacion",IF(AND(NOT(ISBLANK(A37)),NOT(ISBLANK(B37)),NOT(ISBLANK(E37)),ISERROR(VLOOKUP(A37,'ListaN68 02-02-2025'!$A$12:$E$13375,5,0))),"Nuevo",IF(AND(NOT(ISBLANK(A37)),NOT(ISBLANK(B37)),NOT(ISBLANK(E37)),AND(E37-VLOOKUP(A37,'ListaN68 02-02-2025'!$A$12:$E$13375,5,0)>=-2,E37-VLOOKUP(A37,'ListaN68 02-02-2025'!$A$12:$E$13375,5,0)<=2)),"Igual",IF(AND(NOT(ISBLANK(A37)),NOT(ISBLANK(B37)),NOT(ISBLANK(E37)),E37-VLOOKUP(A37,'ListaN68 02-02-2025'!$A$12:$E$13375,5,0)>2),"Aumento",IF(AND(NOT(ISBLANK(A37)),NOT(ISBLANK(B37)),NOT(ISBLANK(E37)),E37-VLOOKUP(A37,'ListaN68 02-02-2025'!$A$12:$E$13375,5,0)<2),"Bajo","Error en codigo"))))))) -> Blanco
A38: 127-60001 | B38: TOMA MULTIPLE DOBLE PATA CHATA BLANCA RICHI | C38: UM 1u | 150u | D38: 21 | E38: 1598.136 | AF38: =IF(AND(ISBLANK(A38),ISBLANK(B38),ISBLANK(E38)),"Blanco",IF(AND(ISBLANK(A38),NOT(ISBLANK(B38))),"Titulo",IF(AND(NOT(ISBLANK(A38)),NOT(ISBLANK(B38)),ISBLANK(E38),IFERROR(FIND("FF--",A38)>1,FALSE)),"F.Comercializacion",IF(AND(NOT(ISBLANK(A38)),NOT(ISBLANK(B38)),NOT(ISBLANK(E38)),ISERROR(VLOOKUP(A38,'ListaN68 02-02-2025'!$A$12:$E$13375,5,0))),"Nuevo",IF(AND(NOT(ISBLANK(A38)),NOT(ISBLANK(B38)),NOT(ISBLANK(E38)),AND(E38-VLOOKUP(A38,'ListaN68 02-02-2025'!$A$12:$E$13375,5,0)>=-2,E38-VLOOKUP(A38,'ListaN68 02-02-2025'!$A$12:$E$13375,5,0)<=2)),"Igual",IF(AND(NOT(ISBLANK(A38)),NOT(ISBLANK(B38)),NOT(ISBLANK(E38)),E38-VLOOKUP(A38,'ListaN68 02-02-2025'!$A$12:$E$13375,5,0)>2),"Aumento",IF(AND(NOT(ISBLANK(A38)),NOT(ISBLANK(B38)),NOT(ISBLANK(E38)),E38-VLOOKUP(A38,'ListaN68 02-02-2025'!$A$12:$E$13375,5,0)<2),"Bajo","Error en codigo"))))))) -> Igual
A39: 127-61001 | B39: TOMA MULTIPLE DOBLE PATA REDONDA BLANCA RICHI | C39: UM 1u | 150u | D39: 21 | E39: 1598.136 | AF39: =IF(AND(ISBLANK(A39),ISBLANK(B39),ISBLANK(E39)),"Blanco",IF(AND(ISBLANK(A39),NOT(ISBLANK(B39))),"Titulo",IF(AND(NOT(ISBLANK(A39)),NOT(ISBLANK(B39)),ISBLANK(E39),IFERROR(FIND("FF--",A39)>1,FALSE)),"F.Comercializacion",IF(AND(NOT(ISBLANK(A39)),NOT(ISBLANK(B39)),NOT(ISBLANK(E39)),ISERROR(VLOOKUP(A39,'ListaN68 02-02-2025'!$A$12:$E$13375,5,0))),"Nuevo",IF(AND(NOT(ISBLANK(A39)),NOT(ISBLANK(B39)),NOT(ISBLANK(E39)),AND(E39-VLOOKUP(A39,'ListaN68 02-02-2025'!$A$12:$E$13375,5,0)>=-2,E39-VLOOKUP(A39,'ListaN68 02-02-2025'!$A$12:$E$13375,5,0)<=2)),"Igual",IF(AND(NOT(ISBLANK(A39)),NOT(ISBLANK(B39)),NOT(ISBLANK(E39)),E39-VLOOKUP(A39,'ListaN68 02-02-2025'!$A$12:$E$13375,5,0)>2),"Aumento",IF(AND(NOT(ISBLANK(A39)),NOT(ISBLANK(B39)),NOT(ISBLANK(E39)),E39-VLOOKUP(A39,'ListaN68 02-02-2025'!$A$12:$E$13375,5,0)<2),"Bajo","Error en codigo"))))))) -> Igual
A40: 3001 | B40: MULTIFICHA TRIPLE PIRAMIDE PREMIUM C/NEU | C40: UM 1u | 100u | D40: 21 | E40: 2707.25 | AF40: =IF(AND(ISBLANK(A40),ISBLANK(B40),ISBLANK(E40)),"Blanco",IF(AND(ISBLANK(A40),NOT(ISBLANK(B40))),"Titulo",IF(AND(NOT(ISBLANK(A40)),NOT(ISBLANK(B40)),ISBLANK(E40),IFERROR(FIND("FF--",A40)>1,FALSE)),"F.Comercializacion",IF(AND(NOT(ISBLANK(A40)),NOT(ISBLANK(B40)),NOT(ISBLANK(E40)),ISERROR(VLOOKUP(A40,'ListaN68 02-02-2025'!$A$12:$E$13375,5,0))),"Nuevo",IF(AND(NOT(ISBLANK(A40)),NOT(ISBLANK(B40)),NOT(ISBLANK(E40)),AND(E40-VLOOKUP(A40,'ListaN68 02-02-2025'!$A$12:$E$13375,5,0)>=-2,E40-VLOOKUP(A40,'ListaN68 02-02-2025'!$A$12:$E$13375,5,0)<=2)),"Igual",IF(AND(NOT(ISBLANK(A40)),NOT(ISBLANK(B40)),NOT(ISBLANK(E40)),E40-VLOOKUP(A40,'ListaN68 02-02-2025'!$A$12:$E$13375,5,0)>2),"Aumento",IF(AND(NOT(ISBLANK(A40)),NOT(ISBLANK(B40)),NOT(ISBLANK(E40)),E40-VLOOKUP(A40,'ListaN68 02-02-2025'!$A$12:$E$13375,5,0)<2),"Bajo","Error en codigo"))))))) -> Igual
A41: 3002 | B41: MULTIFICHA TRIPLE PIRAMIDE PREMIUM | C41: UM 1u | 100u | D41: 21 | E41: 2436 | AF41: =IF(AND(ISBLANK(A41),ISBLANK(B41),ISBLANK(E41)),"Blanco",IF(AND(ISBLANK(A41),NOT(ISBLANK(B41))),"Titulo",IF(AND(NOT(ISBLANK(A41)),NOT(ISBLANK(B41)),ISBLANK(E41),IFERROR(FIND("FF--",A41)>1,FALSE)),"F.Comercializacion",IF(AND(NOT(ISBLANK(A41)),NOT(ISBLANK(B41)),NOT(ISBLANK(E41)),ISERROR(VLOOKUP(A41,'ListaN68 02-02-2025'!$A$12:$E$13375,5,0))),"Nuevo",IF(AND(NOT(ISBLANK(A41)),NOT(ISBLANK(B41)),NOT(ISBLANK(E41)),AND(E41-VLOOKUP(A41,'ListaN68 02-02-2025'!$A$12:$E$13375,5,0)>=-2,E41-VLOOKUP(A41,'ListaN68 02-02-2025'!$A$12:$E$13375,5,0)<=2)),"Igual",IF(AND(NOT(ISBLANK(A41)),NOT(ISBLANK(B41)),NOT(ISBLANK(E41)),E41-VLOOKUP(A41,'ListaN68 02-02-2025'!$A$12:$E$13375,5,0)>2),"Aumento",IF(AND(NOT(ISBLANK(A41)),NOT(ISBLANK(B41)),NOT(ISBLANK(E41)),E41-VLOOKUP(A41,'ListaN68 02-02-2025'!$A$12:$E$13375,5,0)<2),"Bajo","Error en codigo"))))))) -> Igual
A42: MF2 | B42: MULTI-FICHA DOBLE | C42: UM 1u | 80u | D42: 21 | E42: 1551.919 | AF42: =IF(AND(ISBLANK(A42),ISBLANK(B42),ISBLANK(E42)),"Blanco",IF(AND(ISBLANK(A42),NOT(ISBLANK(B42))),"Titulo",IF(AND(NOT(ISBLANK(A42)),NOT(ISBLANK(B42)),ISBLANK(E42),IFERROR(FIND("FF--",A42)>1,FALSE)),"F.Comercializacion",IF(AND(NOT(ISBLANK(A42)),NOT(ISBLANK(B42)),NOT(ISBLANK(E42)),ISERROR(VLOOKUP(A42,'ListaN68 02-02-2025'!$A$12:$E$13375,5,0))),"Nuevo",IF(AND(NOT(ISBLANK(A42)),NOT(ISBLANK(B42)),NOT(ISBLANK(E42)),AND(E42-VLOOKUP(A42,'ListaN68 02-02-2025'!$A$12:$E$13375,5,0)>=-2,E42-VLOOKUP(A42,'ListaN68 02-02-2025'!$A$12:$E$13375,5,0)<=2)),"Igual",IF(AND(NOT(ISBLANK(A42)),NOT(ISBLANK(B42)),NOT(ISBLANK(E42)),E42-VLOOKUP(A42,'ListaN68 02-02-2025'!$A$12:$E$13375,5,0)>2),"Aumento",IF(AND(NOT(ISBLANK(A42)),NOT(ISBLANK(B42)),NOT(ISBLANK(E42)),E42-VLOOKUP(A42,'ListaN68 02-02-2025'!$A$12:$E$13375,5,0)<2),"Bajo","Error en codigo"))))))) -> Nuevo
A43: MF2C | B43: MULTI-FICHA DOBLE C/NEU | C43: UM 1u | 80u | D43: 21 | E43: 1551.919 | AF43: =IF(AND(ISBLANK(A43),ISBLANK(B43),ISBLANK(E43)),"Blanco",IF(AND(ISBLANK(A43),NOT(ISBLANK(B43))),"Titulo",IF(AND(NOT(ISBLANK(A43)),NOT(ISBLANK(B43)),ISBLANK(E43),IFERROR(FIND("FF--",A43)>1,FALSE)),"F.Comercializacion",IF(AND(NOT(ISBLANK(A43)),NOT(ISBLANK(B43)),NOT(ISBLANK(E43)),ISERROR(VLOOKUP(A43,'ListaN68 02-02-2025'!$A$12:$E$13375,5,0))),"Nuevo",IF(AND(NOT(ISBLANK(A43)),NOT(ISBLANK(B43)),NOT(ISBLANK(E43)),AND(E43-VLOOKUP(A43,'ListaN68 02-02-2025'!$A$12:$E$13375,5,0)>=-2,E43-VLOOKUP(A43,'ListaN68 02-02-2025'!$A$12:$E$13375,5,0)<=2)),"Igual",IF(AND(NOT(ISBLANK(A43)),NOT(ISBLANK(B43)),NOT(ISBLANK(E43)),E43-VLOOKUP(A43,'ListaN68 02-02-2025'!$A$12:$E$13375,5,0)>2),"Aumento",IF(AND(NOT(ISBLANK(A43)),NOT(ISBLANK(B43)),NOT(ISBLANK(E43)),E43-VLOOKUP(A43,'ListaN68 02-02-2025'!$A$12:$E$13375,5,0)<2),"Bajo","Error en codigo"))))))) -> Nuevo
AF44: =IF(AND(ISBLANK(A44),ISBLANK(B44),ISBLANK(E44)),"Blanco",IF(AND(ISBLANK(A44),NOT(ISBLANK(B44))),"Titulo",IF(AND(NOT(ISBLANK(A44)),NOT(ISBLANK(B44)),ISBLANK(E44),IFERROR(FIND("FF--",A44)>1,FALSE)),"F.Comercializacion",IF(AND(NOT(ISBLANK(A44)),NOT(ISBLANK(B44)),NOT(ISBLANK(E44)),ISERROR(VLOOKUP(A44,'ListaN68 02-02-2025'!$A$12:$E$13375,5,0))),"Nuevo",IF(AND(NOT(ISBLANK(A44)),NOT(ISBLANK(B44)),NOT(ISBLANK(E44)),AND(E44-VLOOKUP(A44,'ListaN68 02-02-2025'!$A$12:$E$13375,5,0)>=-2,E44-VLOOKUP(A44,'ListaN68 02-02-2025'!$A$12:$E$13375,5,0)<=2)),"Igual",IF(AND(NOT(ISBLANK(A44)),NOT(ISBLANK(B44)),NOT(ISBLANK(E44)),E44-VLOOKUP(A44,'ListaN68 02-02-2025'!$A$12:$E$13375,5,0)>2),"Aumento",IF(AND(NOT(ISBLANK(A44)),NOT(ISBLANK(B44)),NOT(ISBLANK(E44)),E44-VLOOKUP(A44,'ListaN68 02-02-2025'!$A$12:$E$13375,5,0)<2),"Bajo","Error en codigo"))))))) -> Blanco
B45: FICHAS | AF45: =IF(AND(ISBLANK(A45),ISBLANK(B45),ISBLANK(E45)),"Blanco",IF(AND(ISBLANK(A45),NOT(ISBLANK(B45))),"Titulo",IF(AND(NOT(ISBLANK(A45)),NOT(ISBLANK(B45)),ISBLANK(E45),IFERROR(FIND("FF--",A45)>1,FALSE)),"F.Comercializacion",IF(AND(NOT(ISBLANK(A45)),NOT(ISBLANK(B45)),NOT(ISBLANK(E45)),ISERROR(VLOOKUP(A45,'ListaN68 02-02-2025'!$A$12:$E$13375,5,0))),"Nuevo",IF(AND(NOT(ISBLANK(A45)),NOT(ISBLANK(B45)),NOT(ISBLANK(E45)),AND(E45-VLOOKUP(A45,'ListaN68 02-02-2025'!$A$12:$E$13375,5,0)>=-2,E45-VLOOKUP(A45,'ListaN68 02-02-2025'!$A$12:$E$13375,5,0)<=2)),"Igual",IF(AND(NOT(ISBLANK(A45)),NOT(ISBLANK(B45)),NOT(ISBLANK(E45)),E45-VLOOKUP(A45,'ListaN68 02-02-2025'!$A$12:$E$13375,5,0)>2),"Aumento",IF(AND(NOT(ISBLANK(A45)),NOT(ISBLANK(B45)),NOT(ISBLANK(E45)),E45-VLOOKUP(A45,'ListaN68 02-02-2025'!$A$12:$E$13375,5,0)<2),"Bajo","Error en codigo"))))))) -> Titulo
...

Sheet ListaN68 02-02-2025
E1: $
B8: DISTRI-SAL
A14: CODIGO | B14: DESCRIPCION | C14: Cantidad x bulto | D14: IVA | E14: PRECIO SIN IVA | F14: variacion respecto a lista anterior (aplicado en lista)
B16: ELECTRONICA
A18: CRJ-11 | B18: CONECTOR MACHO RJ-11 6 CONTACTOS | C18: UM 1u | D18: 21 | E18: 56.26
A19: CRJ-45 | B19: CONECTOR MACHO RJ-45 8 CONTACTOS | C19: UM 1u | D19: 21 | E19: 118.77
A20: CRJ-9 | B20: CONECTOR MACHO RJ-9 4 CONTACTOS | C20: UM 1u | D20: 21 | E20: 56.26
A21: HDMI | B21: CABLE HDMI A HDMI X1.5MTS | C21: UM 1u | 10u | D21: 21 | E21: 3375.54
A22: USBM | B22: CABLE USB MACHO A MICRO USB 5 PINES | C22: UM 1u | D22: 21 | E22: 1931.56
A23: USBU | B23: CABLE MACHO USB A USB C 1,5MTS | C23: UM 1u | 25u | D23: 21 | E23: 2187.85
E24: 0
B25: TRIPLES Y ADAPTADORES | E25: 0
E26: 0
A27: 200 | B27: ADAPTADOR 2A3 T/ KALOP (M 2P - H 3P) | C27: UM 1u | 50u | 500u | D27: 21 | E27: 534.293
A28: 201 | B28: ADAPTADOR 2A3 T/ EXULT (M 2P - H 3P) | C28: UM 1u | 100u | D28: 21 | E28: 348.874
A29: 210 | B29: ADAPTADOR FICHA TURISTA | C29: UM 1u | 100u | D29: 21 | E29: 972.822
A30: 212 | B30: ADAPTADOR 3A2 MIG (PARED A F.MACHO) | C30: UM 1u | 100u | D30: 21 | E30: 919.636
A31: 215 | B31: TRIPLE IRROMPIBLE MIG | C31: UM 1u | 50u | D31: 21 | E31: 1249.887
A32: 216 | B32: TRIPLE IRROMPIBLE MIG ***CON NEUTRO**** 216 | C32: UM 1u | 50u | D32: 21 | E32: 1249.887
A33: 223 | B33: ADAPTADOR AMERICANO/ALEMAN BCO | C33: UM 1u | 100u | D33: 21 | E33: 892.423
A34: 223-N | B34: ADAPTADOR AMERICANO/ALEMAN NEGRO | C34: UM 1u | 100u | D34: 21 | E34: 892.423
A35: 224 | B35: ADAPTADOR AMERICANO/ALEMAN P/PLANA BCO | C35: UM 1u | 100u | D35: 21 | E35: 919.636
A36: 224-N | B36: ADAPTADOR AMERICANO/ALEMAN P/PLANA NEGRO | C36: UM 1u | 100u | D36: 21 | E36: 919.636
A37: 230 | B37: ADAPTADOR MULTIFUNCION | C37: UM 1u | 100u | D37: 21 | E37: 941.899
A38: LWW-K3 | B38: ADAPTADOR VIAJERO UNIVERSAL C/ FICHA | C38: UM 1u | 20u | 600u | D38: 21 | E38: 1571.945 | F38: 0.0068728522
A39: MU-A3 | B39: ADAPTADOR VIAJERO S/USB | C39: UM 1u | 20u | 200u | D39: 21 | E39: 3441.285 | F39: 0.0068728522
A40: MU-A4 | B40: ADAPTADOR VIAJERO C/USB | C40: UM 1u | 20u | 200u | D40: 21 | E40: 8581.97 | F40: 0.0068728522
A41: PE-727 | B41: ADAPTADOR VIAJERO UNIVERSAL | C41: UM 1u | 20u | 1000u | D41: 21 | E41: 597.72 | F41: 0.0068728522
E42: 0
B43: MULTI-FICHAS | E43: 0
E44: 0
A45: 127-60001 | B45: TOMA MULTIPLE DOBLE PATA CHATA BLANCA RICHI | C45: UM 1u | 150u | D45: 21 | E45: 1598.136
A46: 127-61001 | B46: TOMA MULTIPLE DOBLE PATA REDONDA BLANCA RICHI | C46: UM 1u | 150u | D46: 21 | E46: 1598.136
A47: 3001 | B47: MULTIFICHA TRIPLE PIRAMIDE PREMIUM C/NEU | C47: UM 1u | 100u | D47: 21 | E47: 2707.25
A48: 3002 | B48: MULTIFICHA TRIPLE PIRAMIDE PREMIUM | C48: UM 1u | 100u | D48: 21 | E48: 2436
E49: 0
B50: FICHAS | E50: 0
E51: 0
A52: 121 | B52: FICHA LONGITUDINAL C/NEU MACHO BLANCO MIG | C52: UM 1u | 50u | D52: 21 | E52: 957.856
A53: 121/N | B53: FICHA LONGITUDINAL C/NEU MACHO NEGRO MIG | C53: UM 1u | 50u | D53: 21 | E53: 957.856
...

Sheet Indice
A1: =HYPERLINK('ListaN69 09-02-2025'!$B$9,"Electronica") -> Electronica | C1: =HYPERLINK('ListaN69 09-02-2025'!B9,"Electronica") -> Electronica | H1: CABLE TIPO TALLER ECONOMICO | M1: ARTEFACTOS DE INTERIOR P/LAMPARAS DE BAJO CONSUMO | S1: ANAFES Y CALENTADORES | X1: SOPAPAS PVC | AC1: VARIOS
A2: =HYPERLINK('ListaN69 09-02-2025'!$B$9,"Electronica") -> Electronica | C2: CAÑO RIGIDO PVC DOBLADO EN FRIO | H2: CABLE ECONOMICO TIPO TALLER 5X1 ROLLO | M2: ILUMINACION/LISTONES | S2: REGULADORES GAS ENVASADO | X2: TUBOS EXTENSIBLES SANITARIOS | AC2: PISTOLAS Y BARRAS DE SICLICONA
A3: MULTI-FICHAS | C3: ACCESORIOS PARA CAÑO CURVABLE EN FRIO | H3: CABLE TIPO TALLER NORMALIZADO | M3: LISTONES BAJO MESADA | S3: SOPLETES | X3: SIFONES | AC3: CABALLETES
A4: FICHAS | C4: ACCESORIOS DE PVC (BLANCOS) | H4: CABLE TIPO TALLER EN BOBINA NORMALIZADO | M4: TUBOS FLUORESCENTES Y LED | S4: SOPLETES PARA GAS BUTANO | X4: ACCESORIOS PARA MOCHILAS E INODORO | AC4: GABINETES
A5: PORTALAMPARAS Y ZOCALOS | C5: ACCESORIOS DE HIERRO | H5: CABLE UNIPOLAR ECONOMICO | M5: BALASTROS/ARRANCADORES/CAPASITORES | S5: ACCESORIOS P/SOPLETES | X5: AUTOMATICOS PARA TANQUE | AC5: GABINETES METALICOS IP65
A6: FICHAS INDUSTRIALES | C6: GRAMPAS OMEGA Y 1/2 OMEGA | H6: CABLE UNIPOLAR EN BOBINA ECONOMICO | M6: LUMINARIAS DE EMRGENCIA LED | S6: MANGUERA GAS | X6: TERMOFUSORAS Y MAQUINA DE PINTAR | AC6: ALARMAS/TIMBRES/SENSORES
A7: INTERRUPTORES ESPECIALES | C7: CABLE CANAL | H7: CABLE UNIPOLAR NORMALIZADO | M7: ILUMINACION/PROYECTORES | S7: MANGUERA CRISTAL | X7: EXTRACTORES DE BAÑO
A8: INTERRUPTORES MINI | C8: ACCESORIOS PARA CABLE CANAL | H8: CABLE UNIPOLAR EN BOBINA NORMALIZADO | M8: iNTERRUPTORES HORARIOS/ SENSORES DE MOV | S8: MANGUERAS PARA HIDROCARBURO | X8: ACOPLES RAPIDOS
A9: INSTRUM.DE MEDICION | C9: PILAR/MEDIDOR | H9: CABLE PARA BOMBA SUMERGIBLE | M9: PROYECTORES DE CUARZO Y LAMPARAS | S9: MANGUERAS DE ALTA PRESION | X9: TERRAJAS
A10: PROTECTORES DE TENSION | C10: CAÑO PILAR | H10: CABLE SUBTERRANEO NORMALIZADO | M10: FOTOCELULAS | S10: ACCESORIOS PARA MANGUERA | X10: CAÑA Y ACCESORIOS DESTAPACION
A11: CAPSULADOS | C11: JABALINAS | H11: CABLE SOLDADURA | M11: ILUMINACION/INTERIOR | S11: MANGUERA AUTO-FLOTANTE PARA PILETA | X11: CINTAS DESTAPACION
A12: LINEA DE SUPERFICIE TAAD | C12: TERMICAS JELUZ | H12: CABLE AUTOMOTOR | M12: ILUMINACION/TORTUGAS Y FAROLES | S12: MEDIA SOMBRA 80% | X12: TEFLON "IGMA PLAST"
A13: LINEA DE SUPERFICIE CIOCCA PLAST | C13: DISYUNTORES JELUZ | H13: CABLE COAXIL/DATOS/COMUNICACION | M13: LUMINARIA DE CALLE | S13: MEDIA SOMBRA PREMIUM | X13: CINTA DE TEFLON TACSA
A14: LINEA DE SUPERFICIE MIG | C14: CONTACTORES MODULARES BAW | H14: ZAPATILLAS | M14: PORTATILES | S14: MEDIA SOMBRA 90% | X14: CINTA REFRIGERACION
A15: MODULOS LINEA VIEJA | C15: Contactores tripolares (bobina CA 50-60Hz) BAW | H15: ZAPATILLAS TOMACORRIENTE GENESIS | M15: LAMPARAS LED | S15: RAFIAS/CUBRE CERCOS | X15: CINTAS DE PAPEL TACSA
A16: MODULOS VERONA 2000 | C16: INTERRUPTORES DIFERENCIALES | H16: CINTAS PASACABLE PROFESIONAL VIYILANT | M16: LAMPARAS INCANDESC/BAJO CONS. | S16: MOSQUITEROS PLASTICOS | X16: CINTA MULTI PROPOSITO TACSA
A17: LINEA ARMADA DALY (MIG) | C17: Reles de protección | H17: CINTA PASACABLE VIYILANT | M17: LAMPARAS LED C/FUNCIONES | S17: TEJIDO DE ALAMBRE ELECTROSOLDADO | X17: TANZA
A18: LINEA ARMADA JELUZ | C18: Interruptores termomagnéticos | H18: CINTA PASA CABLE ALMA DE ACERO VIYILANT | M18: LAMPARAS LED FANTASIA | S18: POLIETILENO CRISTAL | X18: NIVELES
... A27: CAÑOS DE HIERRO | C27: CABLE TIPO TALLER EN BOBINA ECONOMICO | H27: CLIPS PARA BATERIA AISLADOS | M27: QUEMADORES INFRARROJOS | S27: GRIFERIAS | X27: ACCESORIOS PARA COMPRESOR Y SOLDADORA

Sheet Mis precios
AC1: ='ListaN69 09-02-2025'!AF1 -> 0
B3: Ver precios con iva? | C3: NO | AC3: ='ListaN69 09-02-2025'!AF2 -> 0
B4: Aplicar descuento por factura? | C4: NO
B5: Mi descuento | C5: 0 | AC5: ='ListaN69 09-02-2025'!AF3 -> 0
B6: Mi Ganancia | C6: 0 | AC6: ='ListaN69 09-02-2025'!AF4 -> 0
AC7: ='ListaN69 09-02-2025'!AF5 -> 0
AC8: ='ListaN69 09-02-2025'!AF6 -> 0
A9: CODIGO | B9: DESCRIPCION | C9: Cantidad x bulto | D9: Alicuota IVA | E9: Mi costo | F9: Mi precio de venta | AC9: ='ListaN69 09-02-2025'!AF7 -> 0
AC10: ='ListaN69 09-02-2025'!AF8 -> Blanco
B11: ELECTRONICA | AC11: ='ListaN69 09-02-2025'!AF9 -> Titulo
AC12: ='ListaN69 09-02-2025'!AF10 -> Blanco
A13: CRJ-11 | B13: CONECTOR MACHO RJ-11 6 CONTACTOS | C13: UM 1u | D13: 21 | E13: =IFERROR(VLOOKUP(A13,'ListaN69 09-02-2025'!$A$9:$E$9716,5,0)*IF($C$3="SI",((D4010/100)+1),1)*IF(AND($C$3="SI",$C$4="SI"),IF(D4010=21,0.92,IF(D4010=10.5,0.96,1)),1)*IF(ISNUMBER($C$5),1-$C$5,1),"-") -> 56.26 | F13: =IFERROR(E13*IF(ISNUMBER($C$6),1+$C$6,1),"-") -> 56.26 | AC13: ='ListaN69 09-02-2025'!AF11 -> Igual
A14: CRJ-45 | B14: CONECTOR MACHO RJ-45 8 CONTACTOS | C14: UM 1u | D14: 21 | E14: =IFERROR(VLOOKUP(A14,'ListaN69 09-02-2025'!$A$9:$E$9716,5,0)*IF($C$3="SI",((D4011/100)+1),1)*IF(AND($C$3="SI",$C$4="SI"),IF(D4011=21,0.92,IF(D4011=10.5,0.96,1)),1)*IF(ISNUMBER($C$5),1-$C$5,1),"-") -> 118.77 | F14: =IFERROR(E14*IF(ISNUMBER($C$6),1+$C$6,1),"-") -> 118.77 | AC14: ='ListaN69 09-02-2025'!AF12 -> Igual
A15: CRJ-9 | B15: CONECTOR MACHO RJ-9 4 CONTACTOS | C15: UM 1u | D15: 21 | E15: =IFERROR(VLOOKUP(A15,'ListaN69 09-02-2025'!$A$9:$E$9716,5,0)*IF($C$3="SI",((D4012/100)+1),1)*IF(AND($C$3="SI",$C$4="SI"),IF(D4012=21,0.92,IF(D4012=10.5,0.96,1)),1)*IF(ISNUMBER($C$5),1-$C$5,1),"-") -> 56.26 | F15: =IFERROR(E15*IF(ISNUMBER($C$6),1+$C$6,1),"-") -> 56.26 | AC15: ='ListaN69 09-02-2025'!AF13 -> Igual
A16: HDMI | B16: CABLE HDMI A HDMI X1.5MTS | C16: UM 1u | 10u | D16: 21 | E16: =IFERROR(VLOOKUP(A16,'ListaN69 09-02-2025'!$A$9:$E$9716,5,0)*IF($C$3="SI",((D4013/100)+1),1)*IF(AND($C$3="SI",$C$4="SI"),IF(D4013=21,0.92,IF(D4013=10.5,0.96,1)),1)*IF(ISNUMBER($C$5),1-$C$5,1),"-") -> 3375.54 | F16: =IFERROR(E16*IF(ISNUMBER($C$6),1+$C$6,1),"-") -> 3375.54 | AC16: ='ListaN69 09-02-2025'!AF14 -> Igual
A17: USBM | B17: CABLE USB MACHO A MICRO USB 5 PINES | C17: UM 1u | D17: 21 | E17: =IFERROR(VLOOKUP(A17,'ListaN69 09-02-2025'!$A$9:$E$9716,5,0)*IF($C$3="SI",((D4014/100)+1),1)*IF(AND($C$3="SI",$C$4="SI"),IF(D4014=21,0.92,IF(D4014=10.5,0.96,1)),1)*IF(ISNUMBER($C$5),1-$C$5,1),"-") -> 1931.56 | F17: =IFERROR(E17*IF(ISNUMBER($C$6),1+$C$6,1),"-") -> 1931.56 | AC17: ='ListaN69 09-02-2025'!AF15 -> Igual
A18: USBU | B18: CABLE MACHO USB A USB C 1,5MTS | C18: UM 1u | 25u | D18: 21 | E18: =IFERROR(VLOOKUP(A18,'ListaN69 09-02-2025'!$A$9:$E$9716,5,0)*IF($C$3="SI",((D4015/100)+1),1)*IF(AND($C$3="SI",$C$4="SI"),IF(D4015=21,0.92,IF(D4015=10.5,0.96,1)),1)*IF(ISNUMBER($C$5),1-$C$5,1),"-") -> 2187.85 | F18: =IFERROR(E18*IF(ISNUMBER($C$6),1+$C$6,1),"-") -> 2187.85 | AC18: ='ListaN69 09-02-2025'!AF16 -> Igual
E19: =IFERROR(VLOOKUP(A19,'ListaN69 09-02-2025'!$A$9:$E$9716,5,0)*IF($C$3="SI",((D4016/100)+1),1)*IF(AND($C$3="SI",$C$4="SI"),IF(D4016=21,0.92,IF(D4016=10.5,0.96,1)),1)*IF(ISNUMBER($C$5),1-$C$5,1),"-") -> - | F19: =IFERROR(E19*IF(ISNUMBER($C$6),1+$C$6,1),"-") -> - | AC19: ='ListaN69 09-02-2025'!AF17 -> Blanco
B20: TRIPLES Y ADAPTADORES | E20: =IFERROR(VLOOKUP(A20,'ListaN69 09-02-2025'!$A$9:$E$9716,5,0)*IF($C$3="SI",((D4017/100)+1),1)*IF(AND($C$3="SI",$C$4="SI"),IF(D4017=21,0.92,IF(D4017=10.5,0.96,1)),1)*IF(ISNUMBER($C$5),1-$C$5,1),"-") -> - | F20: =IFERROR(E20*IF(ISNUMBER($C$6),1+$C$6,1),"-") -> - | AC20: ='ListaN69 09-02-2025'!AF18 -> Titulo
E21: =IFERROR(VLOOKUP(A21,'ListaN69 09-02-2025'!$A$9:$E$9716,5,0)*IF($C$3="SI",((D4018/100)+1),1)*IF(AND($C$3="SI",$C$4="SI"),IF(D4018=21,0.92,IF(D4018=10.5,0.96,1)),1)*IF(ISNUMBER($C$5),1-$C$5,1),"-") -> - | F21: =IFERROR(E21*IF(ISNUMBER($C$6),1+$C$6,1),"-") -> - | AC21: ='ListaN69 09-02-2025'!AF19 -> Blanco
A22: 200 | B22: ADAPTADOR 2A3 T/ KALOP (M 2P - H 3P) | C22: UM 1u | 50u | 500u | D22: 21 | E22: =IFERROR(VLOOKUP(A22,'ListaN69 09-02-2025'!$A$9:$E$9716,5,0)*IF($C$3="SI",((D4019/100)+1),1)*IF(AND($C$3="SI",$C$4="SI"),IF(D4019=21,0.92,IF(D4019=10.5,0.96,1)),1)*IF(ISNUMBER($C$5),1-$C$5,1),"-") -> 534.293 | F22: =IFERROR(E22*IF(ISNUMBER($C$6),1+$C$6,1),"-") -> 534.293 | AC22: ='ListaN69 09-02-2025'!AF20 -> Igual
A23: 201 | B23: ADAPTADOR 2A3 T/ EXULT (M 2P - H 3P) | C23: UM 1u | 100u | D23: 21 | E23: =IFERROR(VLOOKUP(A23,'ListaN69 09-02-2025'!$A$9:$E$9716,5,0)*IF($C$3="SI",((D4020/100)+1),1)*IF(AND($C$3="SI",$C$4="SI"),IF(D4020=21,0.92,IF(D4020=10.5,0.96,1)),1)*IF(ISNUMBER($C$5),1-$C$5,1),"-") -> 348.874 | F23: =IFERROR(E23*IF(ISNUMBER($C$6),1+$C$6,1),"-") -> 348.874 | AC23: ='ListaN69 09-02-2025'!AF21 -> Igual
A24: 210 | B24: ADAPTADOR FICHA TURISTA | C24: UM 1u | 100u | D24: 21 | E24: =IFERROR(VLOOKUP(A24,'ListaN69 09-02-2025'!$A$9:$E$9716,5,0)*IF($C$3="SI",((D4021/100)+1),1)*IF(AND($C$3="SI",$C$4="SI"),IF(D4021=21,0.92,IF(D4021=10.5,0.96,1)),1)*IF(ISNUMBER($C$5),1-$C$5,1),"-") -> 972.822 | F24: =IFERROR(E24*IF(ISNUMBER($C$6),1+$C$6,1),"-") -> 972.822 | AC24: ='ListaN69 09-02-2025'!AF22 -> Igual
A25: 212 | B25: ADAPTADOR 3A2 MIG (PARED A F.MACHO) | C25: UM 1u | 100u | D25: 21 | E25: =IFERROR(VLOOKUP(A25,'ListaN69 09-02-2025'!$A$9:$E$9716,5,0)*IF($C$3="SI",((D4022/100)+1),1)*IF(AND($C$3="SI",$C$4="SI"),IF(D4022=21,0.92,IF(D4022=10.5,0.96,1)),1)*IF(ISNUMBER($C$5),1-$C$5,1),"-") -> 919.636 | F25: =IFERROR(E25*IF(ISNUMBER($C$6),1+$C$6,1),"-") -> 919.636 | AC25: ='ListaN69 09-02-2025'!AF23 -> Igual
A26: 215 | B26: TRIPLE IRROMPIBLE MIG | C26: UM 1u | 50u | D26: 21 | E26: =IFERROR(VLOOKUP(A26,'ListaN69 09-02-2025'!$A$9:$E$9716,5,0)*IF($C$3="SI",((D4023/100)+1),1)*IF(AND($C$3="SI",$C$4="SI"),IF(D4023=21,0.92,IF(D4023=10.5,0.96,1)),1)*IF(ISNUMBER($C$5),1-$C$5,1),"-") -> 1249.887 | F26: =IFERROR(E26*IF(ISNUMBER($C$6),1+$C$6,1),"-") -> 1249.887 | AC26: ='ListaN69 09-02-2025'!AF24 -> Igual
A27: 216 | B27: TRIPLE IRROMPIBLE MIG ***CON NEUTRO**** 216 | C27: UM 1u | 50u | D27: 21 | E27: =IFERROR(VLOOKUP(A27,'ListaN69 09-02-2025'!$A$9:$E$9716,5,0)*IF($C$3="SI",((D4024/100)+1),1)*IF(AND($C$3="SI",$C$4="SI"),IF(D4024=21,0.92,IF(D4024=10.5,0.96,1)),1)*IF(ISNUMBER($C$5),1-$C$5,1),"-") -> 1249.887 | F27: =IFERROR(E27*IF(ISNUMBER($C$6),1+$C$6,1),"-") -> 1249.887 | AC27: ='ListaN69 09-02-2025'!AF25 -> Igual
A28: 223 | B28: ADAPTADOR AMERICANO/ALEMAN BCO | C28: UM 1u | 100u | D28: 21 | E28: =IFERROR(VLOOKUP(A28,'ListaN69 09-02-2025'!$A$9:$E$9716,5,0)*IF($C$3="SI",((D4025/100)+1),1)*IF(AND($C$3="SI",$C$4="SI"),IF(D4025=21,0.92,IF(D4025=10.5,0.96,1)),1)*IF(ISNUMBER($C$5),1-$C$5,1),"-") -> 892.423 | F28: =IFERROR(E28*IF(ISNUMBER($C$6),1+$C$6,1),"-") -> 892.423 | AC28: ='ListaN69 09-02-2025'!AF26 -> Igual
A29: 223-N | B29: ADAPTADOR AMERICANO/ALEMAN NEGRO | C29: UM 1u | 100u | D29: 21 | E29: =IFERROR(VLOOKUP(A29,'ListaN69 09-02-2025'!$A$9:$E$9716,5,0)*IF($C$3="SI",((D4026/100)+1),1)*IF(AND($C$3="SI",$C$4="SI"),IF(D4026=21,0.92,IF(D4026=10.5,0.96,1)),1)*IF(ISNUMBER($C$5),1-$C$5,1),"-") -> 892.423 | F29: =IFERROR(E29*IF(ISNUMBER($C$6),1+$C$6,1),"-") -> 892.423 | AC29: ='ListaN69 09-02-2025'!AF27 -> Igual
A30: 224 | B30: ADAPTADOR AMERICANO/ALEMAN P/PLANA BCO | C30: UM 1u | 100u | D30: 21 | E30: =IFERROR(VLOOKUP(A30,'ListaN69 09-02-2025'!$A$9:$E$9716,5,0)*IF($C$3="SI",((D4027/100)+1),1)*IF(AND($C$3="SI",$C$4="SI"),IF(D4027=21,0.92,IF(D4027=10.5,0.96,1)),1)*IF(ISNUMBER($C$5),1-$C$5,1),"-") -> 919.636 | F30: =IFERROR(E30*IF(ISNUMBER($C$6),1+$C$6,1),"-") -> 919.636 | AC30: ='ListaN69 09-02-2025'!AF28 -> Igual
A31: 224-N | B31: ADAPTADOR AMERICANO/ALEMAN P/PLANA NEGRO | C31: UM 1u | 100u | D31: 21 | E31: =IFERROR(VLOOKUP(A31,'ListaN69 09-02-2025'!$A$9:$E$9716,5,0)*IF($C$3="SI",((D4028/100)+1),1)*IF(AND($C$3="SI",$C$4="SI"),IF(D4028=21,0.92,IF(D4028=10.5,0.96,1)),1)*IF(ISNUMBER($C$5),1-$C$5,1),"-") -> 919.636 | F31: =IFERROR(E31*IF(ISNUMBER($C$6),1+$C$6,1),"-") -> 919.636 | AC31: ='ListaN69 09-02-2025'!AF29 -> Igual
A32: 230 | B32: ADAPTADOR MULTIFUNCION | C32: UM 1u | 100u | D32: 21 | E32: =IFERROR(VLOOKUP(A32,'ListaN69 09-02-2025'!$A$9:$E$9716,5,0)*IF($C$3="SI",((D4029/100)+1),1)*IF(AND($C$3="SI",$C$4="SI"),IF(D4029=21,0.92,IF(D4029=10.5,0.96,1)),1)*IF(ISNUMBER($C$5),1-$C$5,1),"-") -> 941.899 | F32: =IFERROR(E32*IF(ISNUMBER($C$6),1+$C$6,1),"-") -> 941.899 | AC32: ='ListaN69 09-02-2025'!AF30 -> Igual
A33: LWW-K3 | B33: ADAPTADOR VIAJERO UNIVERSAL C/ FICHA | C33: UM 1u | 20u | 600u | D33: 21 | E33: =IFERROR(VLOOKUP(A33,'ListaN69 09-02-2025'!$A$9:$E$9716,5,0)*IF($C$3="SI",((D4030/100)+1),1)*IF(AND($C$3="SI",$C$4="SI"),IF(D4030=21,0.92,IF(D4030=10.5,0.96,1)),1)*IF(ISNUMBER($C$5),1-$C$5,1),"-") -> 1561.215 | F33: =IFERROR(E33*IF(ISNUMBER($C$6),1+$C$6,1),"-") -> 1561.215 | AC33: ='ListaN69 09-02-2025'!AF31 -> Bajo
A34: MU-A3 | B34: ADAPTADOR VIAJERO S/USB | C34: UM 1u | 20u | 200u | D34: 21 | E34: =IFERROR(VLOOKUP(A34,'ListaN69 09-02-2025'!$A$9:$E$9716,5,0)*IF($C$3="SI",((D4031/100)+1),1)*IF(AND($C$3="SI",$C$4="SI"),IF(D4031=21,0.92,IF(D4031=10.5,0.96,1)),1)*IF(ISNUMBER($C$5),1-$C$5,1),"-") -> 3417.795 | F34: =IFERROR(E34*IF(ISNUMBER($C$6),1+$C$6,1),"-") -> 3417.795 | AC34: ='ListaN69 09-02-2025'!AF32 -> Bajo
A35: MU-A4 | B35: ADAPTADOR VIAJERO C/USB | C35: UM 1u | 20u | 200u | D35: 21 | E35: =IFERROR(VLOOKUP(A35,'ListaN69 09-02-2025'!$A$9:$E$9716,5,0)*IF($C$3="SI",((D4032/100)+1),1)*IF(AND($C$3="SI",$C$4="SI"),IF(D4032=21,0.92,IF(D4032=10.5,0.96,1)),1)*IF(ISNUMBER($C$5),1-$C$5,1),"-") -> 8523.39 | F35: =IFERROR(E35*IF(ISNUMBER($C$6),1+$C$6,1),"-") -> 8523.39 | AC35: ='ListaN69 09-02-2025'!AF33 -> Bajo
A36: PE-727 | B36: ADAPTADOR VIAJERO UNIVERSAL | C36: UM 1u | 20u | 1000u | D36: 21 | E36: =IFERROR(VLOOKUP(A36,'ListaN69 09-02-2025'!$A$9:$E$9716,5,0)*IF($C$3="SI",((D4033/100)+1),1)*IF(AND($C$3="SI",$C$4="SI"),IF(D4033=21,0.92,IF(D4033=10.5,0.96,1)),1)*IF(ISNUMBER($C$5),1-$C$5,1),"-") -> 593.64 | F36: =IFERROR(E36*IF(ISNUMBER($C$6),1+$C$6,1),"-") -> 593.64 | AC36: ='ListaN69 09-02-2025'!AF34 -> Bajo
E37: =IFERROR(VLOOKUP(A37,'ListaN69 09-02-2025'!$A$9:$E$9716,5,0)*IF($C$3="SI",((D4034/100)+1),1)*IF(AND($C$3="SI",$C$4="SI"),IF(D4034=21,0.92,IF(D4034=10.5,0.96,1)),1)*IF(ISNUMBER($C$5),1-$C$5,1),"-") -> - | F37: =IFERROR(E37*IF(ISNUMBER($C$6),1+$C$6,1),"-") -> - | AC37: ='ListaN69 09-02-2025'!AF35 -> Blanco
B38: MULTI-FICHAS | E38: =IFERROR(VLOOKUP(A38,'ListaN69 09-02-2025'!$A$9:$E$9716,5,0)*IF($C$3="SI",((D4035/100)+1),1)*IF(AND($C$3="SI",$C$4="SI"),IF(D4035=21,0.92,IF(D4035=10.5,0.96,1)),1)*IF(ISNUMBER($C$5),1-$C$5,1),"-") -> - | F38: =IFERROR(E38*IF(ISNUMBER($C$6),1+$C$6,1),"-") -> - | AC38: ='ListaN69 09-02-2025'!AF36 -> Titulo
E39: =IFERROR(VLOOKUP(A39,'ListaN69 09-02-2025'!$A$9:$E$9716,5,0)*IF($C$3="SI",((D4036/100)+1),1)*IF(AND($C$3="SI",$C$4="SI"),IF(D4036=21,0.92,IF(D4036=10.5,0.96,1)),1)*IF(ISNUMBER($C$5),1-$C$5,1),"-") -> - | F39: =IFERROR(E39*IF(ISNUMBER($C$6),1+$C$6,1),"-") -> - | AC39: ='ListaN69 09-02-2025'!AF37 -> Blanco
A40: 127-60001 | B40: TOMA MULTIPLE DOBLE PATA CHATA BLANCA RICHI | C40: UM 1u | 150u | D40: 21 | E40: =IFERROR(VLOOKUP(A40,'ListaN69 09-02-2025'!$A$9:$E$9716,5,0)*IF($C$3="SI",((D4037/100)+1),1)*IF(AND($C$3="SI",$C$4="SI"),IF(D4037=21,0.92,IF(D4037=10.5,0.96,1)),1)*IF(ISNUMBER($C$5),1-$C$5,1),"-") -> 1598.136 | F40: =IFERROR(E40*IF(ISNUMBER($C$6),1+$C$6,1),"-") -> 1598.136 | AC40: ='ListaN69 09-02-2025'!AF38 -> Igual
A41: 127-61001 | B41: TOMA MULTIPLE DOBLE PATA REDONDA BLANCA RICHI | C41: UM 1u | 150u | D41: 21 | E41: =IFERROR(VLOOKUP(A41,'ListaN69 09-02-2025'!$A$9:$E$9716,5,0)*IF($C$3="SI",((D4038/100)+1),1)*IF(AND($C$3="SI",$C$4="SI"),IF(D4038=21,0.92,IF(D4038=10.5,0.96,1)),1)*IF(ISNUMBER($C$5),1-$C$5,1),"-") -> 1598.136 | F41: =IFERROR(E41*IF(ISNUMBER($C$6),1+$C$6,1),"-") -> 1598.136 | AC41: ='ListaN69 09-02-2025'!AF39 -> Igual
...

Sheet Mi pedido
C13: Ver precios con iva?
C14: Aplicar descuento por factura?
C15: Mi descuento
B18: Codigo | C18: Descripcion | D18: bulto | E18: iva | F18: Cantidad | G18: Precio | I18: Total
C19: =IF(ISBLANK(B19),"",IFERROR(VLOOKUP(B19,'ListaN69 09-02-2025'!$A$11:$E$10140,2,0),"No se encuentra el articulo en la lista")) | D19: =IF(ISBLANK(B19),"",IFERROR(VLOOKUP(B19,'ListaN69 09-02-2025'!$A$11:$E$10140,3,0),"-")) | E19: =IF(ISBLANK(B19),"",IFERROR(VLOOKUP(B19,'ListaN69 09-02-2025'!$A$11:$E$10140,4,0),"-")) | G19: =IF(ISBLANK(B19),"",IFERROR(VLOOKUP(B19,'ListaN69 09-02-2025'!$A$11:$E$10140,5,0)*IF(ISNUMBER($D$15),1-$D$15,1)*IF($D$13="SI",((E19/100)+1),1)*IF(AND($D$13="SI",$D$14="SI"),IF(E19=21,0.92,IF(E19=10.5,0.96,1)),1),"-")) | I19: =IF(AND(ISNUMBER(F19),ISNUMBER(G19)),G19*F19,0) -> 0
C20: =IF(ISBLANK(B20),"",IFERROR(VLOOKUP(B20,'ListaN69 09-02-2025'!$A$11:$E$10140,2,0),"No se encuentra el articulo en la lista")) | D20: =IF(ISBLANK(B20),"",IFERROR(VLOOKUP(B20,'ListaN69 09-02-2025'!$A$11:$E$10140,3,0),"-")) | E20: =IF(ISBLANK(B20),"",IFERROR(VLOOKUP(B20,'ListaN69 09-02-2025'!$A$11:$E$10140,4,0),"-")) | G20: =IF(ISBLANK(B20),"",IFERROR(VLOOKUP(B20,'ListaN69 09-02-2025'!$A$11:$E$10140,5,0)*IF(ISNUMBER($D$15),1-$D$15,1)*IF($D$13="SI",((E20/100)+1),1)*IF(AND($D$13="SI",$D$14="SI"),IF(E20=21,0.92,IF(E20=10.5,0.96,1)),1),"-")) | I20: =IF(AND(ISNUMBER(F20),ISNUMBER(G20)),G20*F20,0) -> 0
C21: =IF(ISBLANK(B21),"",IFERROR(VLOOKUP(B21,'ListaN69 09-02-2025'!$A$11:$E$10140,2,0),"No se encuentra el articulo en la lista")) | D21: =IF(ISBLANK(B21),"",IFERROR(VLOOKUP(B21,'ListaN69 09-02-2025'!$A$11:$E$10140,3,0),"-")) | E21: =IF(ISBLANK(B21),"",IFERROR(VLOOKUP(B21,'ListaN69 09-02-2025'!$A$11:$E$10140,4,0),"-")) | G21: =IF(ISBLANK(B21),"",IFERROR(VLOOKUP(B21,'ListaN69 09-02-2025'!$A$11:$E$10140,5,0)*IF(ISNUMBER($D$15),1-$D$15,1)*IF($D$13="SI",((E21/100)+1),1)*IF(AND($D$13="SI",$D$14="SI"),IF(E21=21,0.92,IF(E21=10.5,0.96,1)),1),"-")) | I21: =IF(AND(ISNUMBER(F21),ISNUMBER(G21)),G21*F21,0) -> 0
C22: =IF(ISBLANK(B22),"",IFERROR(VLOOKUP(B22,'ListaN69 09-02-2025'!$A$11:$E$10140,2,0),"No se encuentra el articulo en la lista")) | D22: =IF(ISBLANK(B22),"",IFERROR(VLOOKUP(B22,'ListaN69 09-02-2025'!$A$11:$E$10140,3,0),"-")) | E22: =IF(ISBLANK(B22),"",IFERROR(VLOOKUP(B22,'ListaN69 09-02-2025'!$A$11:$E$10140,4,0),"-")) | G22: =IF(ISBLANK(B22),"",IFERROR(VLOOKUP(B22,'ListaN69 09-02-2025'!$A$11:$E$10140,5,0)*IF(ISNUMBER($D$15),1-$D$15,1)*IF($D$13="SI",((E22/100)+1),1)*IF(AND($D$13="SI",$D$14="SI"),IF(E22=21,0.92,IF(E22=10.5,0.96,1)),1),"-")) | I22: =IF(AND(ISNUMBER(F22),ISNUMBER(G22)),G22*F22,0) -> 0
C23: =IF(ISBLANK(B23),"",IFERROR(VLOOKUP(B23,'ListaN69 09-02-2025'!$A$11:$E$10140,2,0),"No se encuentra el articulo en la lista")) | D23: =IF(ISBLANK(B23),"",IFERROR(VLOOKUP(B23,'ListaN69 09-02-2025'!$A$11:$E$10140,3,0),"-")) | E23: =IF(ISBLANK(B23),"",IFERROR(VLOOKUP(B23,'ListaN69 09-02-2025'!$A$11:$E$10140,4,0),"-")) | G23: =IF(ISBLANK(B23),"",IFERROR(VLOOKUP(B23,'ListaN69 09-02-2025'!$A$11:$E$10140,5,0)*IF(ISNUMBER($D$15),1-$D$15,1)*IF($D$13="SI",((E23/100)+1),1)*IF(AND($D$13="SI",$D$14="SI"),IF(E23=21,0.92,IF(E23=10.5,0.96,1)),1),"-")) | I23: =IF(AND(ISNUMBER(F23),ISNUMBER(G23)),G23*F23,0) -> 0
C24: =IF(ISBLANK(B24),"",IFERROR(VLOOKUP(B24,'ListaN69 09-02-2025'!$A$11:$E$10140,2,0),"No se encuentra el articulo en la lista")) | D24: =IF(ISBLANK(B24),"",IFERROR(VLOOKUP(B24,'ListaN69 09-02-2025'!$A$11:$E$10140,3,0),"-")) | E24: =IF(ISBLANK(B24),"",IFERROR(VLOOKUP(B24,'ListaN69 09-02-2025'!$A$11:$E$10140,4,0),"-")) | G24: =IF(ISBLANK(B24),"",IFERROR(VLOOKUP(B24,'ListaN69 09-02-2025'!$A$11:$E$10140,5,0)*IF(ISNUMBER($D$15),1-$D$15,1)*IF($D$13="SI",((E24/100)+1),1)*IF(AND($D$13="SI",$D$14="SI"),IF(E24=21,0.92,IF(E24=10.5,0.96,1)),1),"-")) | I24: =IF(AND(ISNUMBER(F24),ISNUMBER(G24)),G24*F24,0) -> 0
C25: =IF(ISBLANK(B25),"",IFERROR(VLOOKUP(B25,'ListaN69 09-02-2025'!$A$11:$E$10140,2,0),"No se encuentra el articulo en la lista")) | D25: =IF(ISBLANK(B25),"",IFERROR(VLOOKUP(B25,'ListaN69 09-02-2025'!$A$11:$E$10140,3,0),"-")) | E25: =IF(ISBLANK(B25),"",IFERROR(VLOOKUP(B25,'ListaN69 09-02-2025'!$A$11:$E$10140,4,0),"-")) | G25: =IF(ISBLANK(B25),"",IFERROR(VLOOKUP(B25,'ListaN69 09-02-2025'!$A$11:$E$10140,5,0)*IF(ISNUMBER($D$15),1-$D$15,1)*IF($D$13="SI",((E25/100)+1),1)*IF(AND($D$13="SI",$D$14="SI"),IF(E25=21,0.92,IF(E25=10.5,0.96,1)),1),"-")) | I25: =IF(AND(ISNUMBER(F25),ISNUMBER(G25)),G25*F25,0) -> 0
C26: =IF(ISBLANK(B26),"",IFERROR(VLOOKUP(B26,'ListaN69 09-02-2025'!$A$11:$E$10140,2,0),"No se encuentra el articulo en la lista")) | D26: =IF(ISBLANK(B26),"",IFERROR(VLOOKUP(B26,'ListaN69 09-02-2025'!$A$11:$E$10140,3,0),"-")) | E26: =IF(ISBLANK(B26),"",IFERROR(VLOOKUP(B26,'ListaN69 09-02-2025'!$A$11:$E$10140,4,0),"-")) | G26: =IF(ISBLANK(B26),"",IFERROR(VLOOKUP(B26,'ListaN69 09-02-2025'!$A$11:$E$10140,5,0)*IF(ISNUMBER($D$15),1-$D$15,1)*IF($D$13="SI",((E26/100)+1),1)*IF(AND($D$13="SI",$D$14="SI"),IF(E26=21,0.92,IF(E26=10.5,0.96,1)),1),"-")) | I26: =IF(AND(ISNUMBER(F26),ISNUMBER(G26)),G26*F26,0) -> 0
C27: =IF(ISBLANK(B27),"",IFERROR(VLOOKUP(B27,'ListaN69 09-02-2025'!$A$11:$E$10140,2,0),"No se encuentra el articulo en la lista")) | D27: =IF(ISBLANK(B27),"",IFERROR(VLOOKUP(B27,'ListaN69 09-02-2025'!$A$11:$E$10140,3,0),"-")) | E27: =IF(ISBLANK(B27),"",IFERROR(VLOOKUP(B27,'ListaN69 09-02-2025'!$A$11:$E$10140,4,0),"-")) | G27: =IF(ISBLANK(B27),"",IFERROR(VLOOKUP(B27,'ListaN69 09-02-2025'!$A$11:$E$10140,5,0)*IF(ISNUMBER($D$15),1-$D$15,1)*IF($D$13="SI",((E27/100)+1),1)*IF(AND($D$13="SI",$D$14="SI"),IF(E27=21,0.92,IF(E27=10.5,0.96,1)),1),"-")) | I27: =IF(AND(ISNUMBER(F27),ISNUMBER(G27)),G27*F27,0) -> 0
